Workbook
Name a: [1]Ref_Umum!$C$23:$C$28
Name cara_bayar: [2]Ref_Umum!$C$9:$C$12
Name cara_bayar_kontraktual: [2]Ref_Umum!$D$9:$D$10
Name class: ViewSP2D_BLU!$N$1:$N$2
Name data_pembayaran_akun_potongan1: [2]DataPembayaran_BLU!$M$2:$M$394
Name data_pembayaran_akun_potongan2: [2]DataPembayaran_BLU!$O$2:$O$394
Name data_pembayaran_akun_potongan3: [2]DataPembayaran_BLU!$Q$2:$Q$394
Name data_pembayaran_jumlah_potongan1: [2]DataPembayaran_BLU!$N$2:$N$394
Name data_pembayaran_jumlah_potongan2: [2]DataPembayaran_BLU!$P$2:$P$394
Name data_pembayaran_jumlah_potongan3: [2]DataPembayaran_BLU!$R$2:$R$394
Name data_pembayaran_no_kontrak: [2]DataPembayaran_BLU!$H$2:$H$700
Name data_pembayaran_no_transaksi: DataPembayaran_BLU!$A$2:$A$700
Name data_pembayaran_tanggal_kontrak: DataPembayaran_BLU!$I$2:$I$700
Name data_pembayaran_termin_kontrak: DataPembayaran_BLU!$J$2:$J$394
Name data_pembayaran_total_pembayaran: [2]DataPembayaran_BLU!$L$2:$L$1000
Name DATASP2D: DataSP2D_BLU!$B$1:$N$500
Name DATASP2Di: DataSP2D_BLU!$A$1:$N$500
Name DATASPMi: DataPembayaran_BLU!$A$1:$S$493
Name id_kontrak: [2]DataKontrak_BLU!$F$5:$F$285
Name id_trx_kontrak: InputKontrak_BLU!$F$4
Name Jenis_Pagu: Pagu_BLU!$K$1:$U$1
Name jenis_tagihan: [2]Ref_Umum!$C$14:$C$16
Name kode_coa: Pagu_BLU!$I$7:$I$206
Name kode_MAP: [2]Ref_Umum!$H$7:$H$14
Name nama_pejabat: DataPejabat!$B$2:$B$9
Name nip_pejabat: DataPejabat!$C$2:$C$9
Name nomor_kontrak: [2]DataKontrak_BLU!$G$5:$G$285
Name ref_jabatan: [3]Ref_Umum!$U$3:$U$7
Name supplier: [2]Supplier!$B$2:$B$150
Name supplier_alamat: [2]Supplier!$D$2:$D$302
Name supplier_bank: [2]Supplier!$F$2:$F$302
Name supplier_nama_rekening: Supplier!$H$2:$H$302
Name supplier_npwp: [2]Supplier!$E$2:$E301
Name supplier_rekening: [2]Supplier!$G$2:$G$302
Name uraian_pembayaran: DataPembayaran_BLU!$G$2:$G$394

Sheet DASHBOARD
F4: =SUM(Pagu_BLU!$K$2:$K$206) -> 49467824000 | I4: =SUM(data_pembayaran_total_pembayaran) -> 2142401865 | L4: =I4/F4 -> 0.043308997
F7: Pagu Belanja BLU | I7: Realisasi Belanja BLU | L7: Progress Realisasi
F9: =SUMIF(DataPembayaran_BLU!$U$2:$U$700,"Belanja Barang",data_pembayaran_total_pembayaran) -> #VALUE! | I9: =SUMIF(DataPembayaran_BLU!$U$2:$U$700,"Belanja Modal",data_pembayaran_total_pembayaran) -> #VALUE! | L9: =SUM(DataPembayaran_BLU!N:N)+SUM(DataPembayaran_BLU!P:P) -> 228841644
F12: Realisasi Belanja Barang | I12: Realisasi Belanja Modal | L12: Jumlah Potongan SPM
F14: =COUNT(DataPembayaran_BLU!$A$2:$A$700) -> 47 | I14: =SUMIF(DataPembayaran_BLU!$W$2:$W$700,"Sah",data_pembayaran_total_pembayaran) -> #VALUE! | L14: =SUM([3]DataKontrak_BLU!$P$5:$P$104) -> 12445600040
F17: Jumlah SPM Terbit | I17: Realisasi SPM Sudah Disahkan | L17: Nilai SPM Kontraktual
O19: v1 ©2023 viva

Sheet InputKontrak_BLU
E4: ID Trx | F4: 4
E5: Nomor Kontrak | F5: PL.107/0001/PPK.BB/APTP/2026 | K5: Tgl. Kontrak | N5: Jumlah Termin | O5: 12
E6: Addendum Ke- | N6: Termin 1 UM
E7: Nomor Addendum | K7: Tgl. Addendum | N7: Termin 1 | O7: 473782875 | Q7: Angsuran UM 1
E8: Uraian Kontrak | F8: Pengadaan Jasa Outsourching Cleaning Service Terminal dan Pemeliharaan Landscape Bandara 1 Paket | N8: Termin 2 | O8: 473782875 | Q8: Angsuran UM 2
N9: Termin 3 | O9: 473782875 | Q9: Angsuran UM 3
N10: Termin 4 | O10: 473782875 | Q10: Angsuran UM 4
E11: Nama Supplier | F11: PT. INTERCIPTA JASA INDONESIA | N11: Termin 5 | O11: 473782875 | Q11: Angsuran UM 5
E12: Nilai Kontrak | F12: 5685394500 | I12: Mata Uang | J12: IDR | N12: Termin 6 | O12: 473782875 | Q12: Angsuran UM 6
E13: Cara Bayar | F13: Termin | N13: Termin 7 | O13: 473782875 | Q13: Angsuran UM 7
E14: Sistem Bayar | J14: =Pagu_BLU!I51 -> WA.4611.EBA.962.051.A.525119.00001 | N14: Termin 8 | O14: 473782875 | Q14: Angsuran UM 8
N15: Termin 9 | O15: 473782875 | Q15: Angsuran UM 9
E16: J.W. Pekerjaan | F16: 356 | G16: Hari | H16: Tgl. Mulai | I16: 46023 | K16: Tgl. Selesai | L16: 46387 | N16: Termin 10 | O16: 473782875 | Q16: Angsuran UM 10
E17: J.W. Pemeliharaan | H17: Tgl. Mulai | K17: Tgl. Selesai | N17: Termin 11 | O17: 473782875 | Q17: Angsuran UM 11
E18: Ketentuan Sanksi | N18: Termin 12 | O18: 473782875 | Q18: Angsuran UM 12
N19: Termin 13 | Q19: Angsuran UM 13
N20: Termin 14 | Q20: Angsuran UM 14
E21: Penjamin UM | N21: Termin 15 | R21: =SUM(R7:S20) -> 0
E22: No. Jaminan | K22: Tgl. Jaminan
E23: Masa Berlaku | G23: - | H23: Tgl. Mulai | K23: Tgl. Selesai
E25: Koordinat Posisi
E26: PPK | F26: gunawan

Sheet KarwasKontrak_BLU
E1: ID | G1: 003-0-PL.107/0002/PPK.BB/APTP/2026
E2: KARTU MONITORING KONTRAK
E5: Satker | F5: : | G5: 288745 Kantor UPBU Aji Pangeran Tumenggung Pranoto | S5: J.W. Pekerjaan | T5: : | U5: =CONCATENATE(INDEX([3]DataKontrak_BLU!T$5:T$104,MATCH($G$1,id_kontrak,0))," Hari") -> 365 Hari | V5: Tgl. Mulai | W5: : | X5: =IF(INDEX([3]DataKontrak_BLU!U$5:U$104,MATCH($G$1,id_kontrak,0))=0,"",INDEX([3]DataKontrak_BLU!U$5:U$104,MATCH($G$1,id_kontrak,0))) -> 46023 | Y5: Tgl. Selesai | Z5: : | AA5: =IF(INDEX([3]DataKontrak_BLU!V$5:V$104,MATCH($G$1,id_kontrak,0))=0,"",INDEX([3]DataKontrak_BLU!V$5:V$104,MATCH($G$1,id_kontrak,0))) -> 46387
E6: Dokumen | F6: : | G6: DIPA | H6: No. Dok | I6: : | J6: DIPA-022.05.2.288745/2026 | P6: Tgl. Dok | Q6: : | S6: J.W. Pelihara | T6: : | U6: =CONCATENATE(INDEX([3]DataKontrak_BLU!W$5:W$104,MATCH($G$1,id_kontrak,0))," Hari") -> Hari | V6: Tgl. Mulai | W6: : | X6: =IF(INDEX([3]DataKontrak_BLU!X$5:X$104,MATCH($G$1,id_kontrak,0))=0,"",INDEX([3]DataKontrak_BLU!X$5:X$104,MATCH($G$1,id_kontrak,0))) | Y6: Tgl. Selesai | Z6: : | AA6: =IF(INDEX([3]DataKontrak_BLU!Y$5:Y$104,MATCH($G$1,id_kontrak,0))=0,"",INDEX([3]DataKontrak_BLU!Y$5:Y$104,MATCH($G$1,id_kontrak,0)))
E7: ID Kontrak | F7: : | G7: =LEFT($G$1,5) -> 003-0 | H7: Add ke- | I7: : | J7: =IF(INDEX([3]DataKontrak_BLU!I$5:I$104,MATCH($G$1,id_kontrak,0))=0,"",INDEX([3]DataKontrak_BLU!I$5:I$104,MATCH($G$1,id_kontrak,0))) | K7: No. Add | L7: : | M7: =IF(INDEX([3]DataKontrak_BLU!J$5:J$104,MATCH($G$1,id_kontrak,0))=0,"",INDEX([3]DataKontrak_BLU!J$5:J$104,MATCH($G$1,id_kontrak,0))) | P7: Tgl. Add | Q7: : | R7: =IF(INDEX([3]DataKontrak_BLU!K$5:K$104,MATCH($G$1,id_kontrak,0))=0,"",INDEX([3]DataKontrak_BLU!K$5:K$104,MATCH($G$1,id_kontrak,0)))
E8: Nomor Kontrak | F8: : | G8: =INDEX([3]DataKontrak_BLU!G$5:G$104,MATCH($G$1,id_kontrak,0)) -> PL.107/0002/PPK.BB/APTP/2026 | P8: Tgl. Kontrak | Q8: : | S8: Jaminan UM
E9: Uraian Kontrak | F9: : | G9: =INDEX([3]DataKontrak_BLU!L$5:L$104,MATCH($G$1,id_kontrak,0)) -> PENGADAAN JASA OUTSOURCHING PENGAMANAN BANDARA (PERSONIL AVSEC) 1 PAKET | S9: Bank/LK Penjamin | T9: : | U9: =IF(INDEX([3]DataKontrak_BLU!AA$5:AA$104,MATCH($G$1,id_kontrak,0))=0,"",INDEX([3]DataKontrak_BLU!AA$5:AA$104,MATCH($G$1,id_kontrak,0)))
S10: No. Surat Jaminan | T10: : | U10: =IF(INDEX([3]DataKontrak_BLU!AB$5:AB$104,MATCH($G$1,id_kontrak,0))=0,"",INDEX([3]DataKontrak_BLU!AB$5:AB$104,MATCH($G$1,id_kontrak,0))) | X10: Berlaku | Y10: =IF(INDEX([3]DataKontrak_BLU!AE$5:AE$104,MATCH($G$1,id_kontrak,0))=0,"",INDEX([3]DataKontrak_BLU!AE$5:AE$104,MATCH($G$1,id_kontrak,0))) | Z10: sd | AA10: =IF(INDEX([3]DataKontrak_BLU!AF$5:AF$104,MATCH($G$1,id_kontrak,0))=0,"",INDEX([3]DataKontrak_BLU!AF$5:AF$104,MATCH($G$1,id_kontrak,0)))
E11: Nama Rekanan | F11: : | G11: =INDEX([3]DataKontrak_BLU!M$5:M$104,MATCH($G$1,id_kontrak,0)) -> PT. GARUDA TAWAKAL ABADI | K11: NPWP | L11: : | M11: =INDEX(supplier_npwp,MATCH($G$11,supplier,0)) -> 03.008.751.4-617.000 | S11: Jaminan Pemeliharaan
E12: Alamat Rekanan | F12: : | G12: =INDEX(supplier_alamat,MATCH($G$11,supplier,0)) -> Jl. Griyo Mapan Sentosa EA1 No.2B RT.042 RW.005 | S12: Bank/LK Penjamin | T12: :
E13: Nama Bank | F13: : | G13: =INDEX(supplier_bank,MATCH($G$11,supplier,0)) -> Bank Tabungan Negara | M13: No. Rek : | N13: =INDEX(supplier_rekening,MATCH($G$11,supplier,0)) -> 0006201880003220 | S13: No. Surat Jaminan | T13: : | X13: Berlaku | Z13: sd
E14: Cara Bayar | F14: : | G14: =INDEX([3]DataKontrak_BLU!R$5:R$104,MATCH($G$1,id_kontrak,0)) -> Termin | S14: Retensi | T14: : | U14: 0
E15: Sistem Bayar | F15: : | G15: =INDEX([3]DataKontrak_BLU!S$5:S$104,MATCH($G$1,id_kontrak,0)) -> Srkaligus | S15: Dari Nilai | T15: : | U15: Realisasi
E17: Keg/Output/Komponen/Sub/Akun | M17: S.d. Termin Ke | N17: Nilai Realisasi | Q17: PPN | T17: PPH | X17: Jumlah Neto
E18: COA | H18: Nilai
E19: =INDEX([3]DataKontrak_BLU!BM$5:BM$104,MATCH($G$1,id_kontrak,0)) -> WA.4611.EBA.962.051.A.525119.00002 | H19: =INDEX([3]DataKontrak_BLU!P$5:P$104,MATCH($G$1,id_kontrak,0)) -> 6368521200 | M19: =COUNTIF(Realisasi_BLU!$M$11:$N$25,">0") -> 0 | N19: =SUMIF(DataPembayaran_BLU!$H$2:$H$394,KarwasKontrak_BLU!$G$8,data_pembayaran_total_pembayaran) -> #VALUE! | Q19: =SUM(SUMIFS(data_pembayaran_jumlah_potongan1,data_pembayaran_no_kontrak,KarwasKontrak_BLU!$G$8,data_pembayaran_akun_potongan1,"411211"),SUMIFS(data_pembayaran_jumlah_potongan2,data_pembayaran_no_kontrak,KarwasKontrak_BLU!$G$8,data_pembayaran_akun_potongan2,"411211"),SUMIFS(data_pembayaran_jumlah_potongan3,data_pembayaran_no_kontrak,KarwasKontrak_BLU!$G$8,data_pembayaran_akun_potongan3,"411211")) -> #VALUE! | T19: {=SUM(SUMIFS(data_pembayaran_jumlah_potongan1,data_pembayaran_no_kontrak,KarwasKontrak_BLU!$G$8,data_pembayaran_akun_potongan1,{"411121";"411122";"411124"}),SUMIFS(data_pembayaran_jumlah_potongan2,data_pembayaran_no_kontrak,KarwasKontrak_BLU!$G$8,data_pembayaran_akun_potongan2,{"411121";"411122";"411124"}),SUMIFS(data_pembayaran_jumlah_potongan3,data_pembayaran_no_kontrak,KarwasKontrak_BLU!$G$8,data_pembayaran_akun_potongan3,{"411121";"411122";"411124"}))} -> #VALUE! | X19: =$N$19-SUM($Q$19:$W$20) -> #VALUE!
E21: Pagu Kontrak | H21: =H19 -> 6368521200 | N21: =N19 -> #VALUE! | Q21: =Q19 -> #VALUE! | T21: =T19 -> #VALUE! | X21: =X19 -> #VALUE!
E23: Keterangan | F23: BLU
E24: Nilai Kontrak | F24: =INDEX([3]DataKontrak_BLU!P$5:P$104,MATCH($G$1,id_kontrak,0)) -> 6368521200
E25: Nilai Realisasi | F25: =SUMIF(DataPembayaran_BLU!$H$2:$H$394,KarwasKontrak_BLU!$G$8,data_pembayaran_total_pembayaran) -> #VALUE!
E26: Sisa Kontrak | F26: =F24-F25 -> #VALUE!

Sheet Realisasi_BLU
E1: ID | G1: 004-0-PL.107/0001/PPK.BB/APTP/2026
E3: REGISTER DATA REALISASI KONTRAK
E5: Tahun Kontrak | F5: : | G5: 2026
E6: Satuan Kerja | F6: : | G6: 288745 Kantor UPBU Aji Pangeran Tumenggung Pranoto
E7: ID Kontrak | F7: : | G7: =LEFT($G$1,5) -> 004-0 | I7: No. Kontrak | J7: : | K7: =INDEX([3]DataKontrak_BLU!G$5:G$104,MATCH($G$1,id_kontrak,0)) -> PL.107/0001/PPK.BB/APTP/2026 | M7: Tgl. Kontrak | N7: : | O7: =INDEX([3]DataKontrak_BLU!H$5:H$104,MATCH($G$1,id_kontrak,0)) -> 0
E8: Addendum Ke | F8: : | G8: =IF(INDEX([3]DataKontrak_BLU!I$5:I$104,MATCH($G$1,id_kontrak,0))=0,"",INDEX([3]DataKontrak_BLU!I$5:I$104,MATCH($G$1,id_kontrak,0))) | I8: No. Addendum | J8: : | K8: =IF(INDEX([3]DataKontrak_BLU!J$5:J$104,MATCH($G$1,id_kontrak,0))=0,"",INDEX([3]DataKontrak_BLU!J$5:J$104,MATCH($G$1,id_kontrak,0))) | M8: Tgl. Addendum | N8: : | O8: =IF(INDEX([3]DataKontrak_BLU!K$5:K$104,MATCH($G$1,id_kontrak,0))=0,"",INDEX([3]DataKontrak_BLU!K$5:K$104,MATCH($G$1,id_kontrak,0)))
E10: Termin | G10: Uang Muka | H10: Prestasi Pekerjaan | I10: Angsuran UM | K10: Retensi | L10: Nilai Bruto | M10: Nilai Realisasi | O10: PPN | P10: PPH
D11: 1 | E11: I | G11: =INDEX([3]DataKontrak_BLU!$AI$5:$AI$104,MATCH(Realisasi_BLU!$G$1,id_kontrak,0)) -> 0 | H11: =INDEX([3]DataKontrak_BLU!$AJ$5:$AJ$104,MATCH(Realisasi_BLU!$G$1,id_kontrak,0)) -> 473782875 | I11: 0 | K11: 0 | L11: =SUM($G11:$K11) -> 473782875 | M11: =SUMIFS(data_pembayaran_total_pembayaran,data_pembayaran_no_kontrak,Realisasi_BLU!$K$7,data_pembayaran_termin_kontrak,Realisasi_BLU!D11) -> #VALUE! | O11: =SUM(SUMIFS(data_pembayaran_jumlah_potongan1,data_pembayaran_no_kontrak,$K$7,data_pembayaran_akun_potongan1,"411211",data_pembayaran_termin_kontrak,$D11),SUMIFS(data_pembayaran_jumlah_potongan2,data_pembayaran_no_kontrak,$K$7,data_pembayaran_akun_potongan2,"411211",data_pembayaran_termin_kontrak,$D11),SUMIFS(data_pembayaran_jumlah_potongan3,data_pembayaran_no_kontrak,$K$7,data_pembayaran_akun_potongan3,"411211",data_pembayaran_termin_kontrak,$D11)) -> #VALUE! | P11: {=SUM(SUMIFS(data_pembayaran_jumlah_potongan1,data_pembayaran_no_kontrak,$K$7,data_pembayaran_akun_potongan1,{"411121";"411122";"411124"},data_pembayaran_termin_kontrak,$D11),SUMIFS(data_pembayaran_jumlah_potongan2,data_pembayaran_no_kontrak,$K$7,data_pembayaran_akun_potongan2,{"411121";"411122";"411124"},data_pembayaran_termin_kontrak,$D11),SUMIFS(data_pembayaran_jumlah_potongan3,data_pembayaran_no_kontrak,$K$7,data_pembayaran_akun_potongan3,{"411121";"411122";"411124"},data_pembayaran_termin_kontrak,$D11))} -> #VALUE!
D12: 2 | E12: II | G12: 0 | H12: =INDEX([3]DataKontrak_BLU!$AK$5:$AK$104,MATCH(Realisasi_BLU!$G$1,id_kontrak,0)) -> 473782875 | I12: =INDEX(-[3]DataKontrak_BLU!$AY$5:$AY$104,MATCH(Realisasi_BLU!$G$1,id_kontrak,0)) -> 0 | K12: 0 | L12: =SUM($G12:$K12) -> 473782875 | M12: =SUMIFS(data_pembayaran_total_pembayaran,data_pembayaran_no_kontrak,Realisasi_BLU!$K$7,data_pembayaran_termin_kontrak,Realisasi_BLU!D12) -> #VALUE! | O12: =SUM(SUMIFS(data_pembayaran_jumlah_potongan1,data_pembayaran_no_kontrak,$K$7,data_pembayaran_akun_potongan1,"411211",data_pembayaran_termin_kontrak,$D12),SUMIFS(data_pembayaran_jumlah_potongan2,data_pembayaran_no_kontrak,$K$7,data_pembayaran_akun_potongan2,"411211",data_pembayaran_termin_kontrak,$D12),SUMIFS(data_pembayaran_jumlah_potongan3,data_pembayaran_no_kontrak,$K$7,data_pembayaran_akun_potongan3,"411211",data_pembayaran_termin_kontrak,$D12)) -> #VALUE! | P12: {=SUM(SUMIFS(data_pembayaran_jumlah_potongan1,data_pembayaran_no_kontrak,$K$7,data_pembayaran_akun_potongan1,{"411121";"411122";"411124"},data_pembayaran_termin_kontrak,$D12),SUMIFS(data_pembayaran_jumlah_potongan2,data_pembayaran_no_kontrak,$K$7,data_pembayaran_akun_potongan2,{"411121";"411122";"411124"},data_pembayaran_termin_kontrak,$D12),SUMIFS(data_pembayaran_jumlah_potongan3,data_pembayaran_no_kontrak,$K$7,data_pembayaran_akun_potongan3,{"411121";"411122";"411124"},data_pembayaran_termin_kontrak,$D12))} -> #VALUE!
D13: 3 | E13: III | G13: 0 | H13: =INDEX([3]DataKontrak_BLU!$AL$5:$AL$104,MATCH(Realisasi_BLU!$G$1,id_kontrak,0)) -> 473782875 | I13: =INDEX(-[3]DataKontrak_BLU!$AZ$5:$AZ$104,MATCH(Realisasi_BLU!$G$1,id_kontrak,0)) -> 0 | K13: 0 | L13: =SUM($G13:$K13) -> 473782875 | M13: =SUMIFS(data_pembayaran_total_pembayaran,data_pembayaran_no_kontrak,Realisasi_BLU!$K$7,data_pembayaran_termin_kontrak,Realisasi_BLU!D13) -> #VALUE! | O13: =SUM(SUMIFS(data_pembayaran_jumlah_potongan1,data_pembayaran_no_kontrak,$K$7,data_pembayaran_akun_potongan1,"411211",data_pembayaran_termin_kontrak,$D13),SUMIFS(data_pembayaran_jumlah_potongan2,data_pembayaran_no_kontrak,$K$7,data_pembayaran_akun_potongan2,"411211",data_pembayaran_termin_kontrak,$D13),SUMIFS(data_pembayaran_jumlah_potongan3,data_pembayaran_no_kontrak,$K$7,data_pembayaran_akun_potongan3,"411211",data_pembayaran_termin_kontrak,$D13)) -> #VALUE! | P13: {=SUM(SUMIFS(data_pembayaran_jumlah_potongan1,data_pembayaran_no_kontrak,$K$7,data_pembayaran_akun_potongan1,{"411121";"411122";"411124"},data_pembayaran_termin_kontrak,$D13),SUMIFS(data_pembayaran_jumlah_potongan2,data_pembayaran_no_kontrak,$K$7,data_pembayaran_akun_potongan2,{"411121";"411122";"411124"},data_pembayaran_termin_kontrak,$D13),SUMIFS(data_pembayaran_jumlah_potongan3,data_pembayaran_no_kontrak,$K$7,data_pembayaran_akun_potongan3,{"411121";"411122";"411124"},data_pembayaran_termin_kontrak,$D13))} -> #VALUE!
D14: 4 | E14: IV | G14: 0 | H14: =INDEX([3]DataKontrak_BLU!$AM$5:$AM$104,MATCH(Realisasi_BLU!$G$1,id_kontrak,0)) -> 473782875 | I14: =INDEX(-[3]DataKontrak_BLU!$BA$5:$BA$104,MATCH(Realisasi_BLU!$G$1,id_kontrak,0)) -> 0 | K14: 0 | L14: =SUM($G14:$K14) -> 473782875 | M14: =SUMIFS(data_pembayaran_total_pembayaran,data_pembayaran_no_kontrak,Realisasi_BLU!$K$7,data_pembayaran_termin_kontrak,Realisasi_BLU!D14) -> #VALUE! | O14: =SUM(SUMIFS(data_pembayaran_jumlah_potongan1,data_pembayaran_no_kontrak,$K$7,data_pembayaran_akun_potongan1,"411211",data_pembayaran_termin_kontrak,$D14),SUMIFS(data_pembayaran_jumlah_potongan2,data_pembayaran_no_kontrak,$K$7,data_pembayaran_akun_potongan2,"411211",data_pembayaran_termin_kontrak,$D14),SUMIFS(data_pembayaran_jumlah_potongan3,data_pembayaran_no_kontrak,$K$7,data_pembayaran_akun_potongan3,"411211",data_pembayaran_termin_kontrak,$D14)) -> #VALUE! | P14: {=SUM(SUMIFS(data_pembayaran_jumlah_potongan1,data_pembayaran_no_kontrak,$K$7,data_pembayaran_akun_potongan1,{"411121";"411122";"411124"},data_pembayaran_termin_kontrak,$D14),SUMIFS(data_pembayaran_jumlah_potongan2,data_pembayaran_no_kontrak,$K$7,data_pembayaran_akun_potongan2,{"411121";"411122";"411124"},data_pembayaran_termin_kontrak,$D14),SUMIFS(data_pembayaran_jumlah_potongan3,data_pembayaran_no_kontrak,$K$7,data_pembayaran_akun_potongan3,{"411121";"411122";"411124"},data_pembayaran_termin_kontrak,$D14))} -> #VALUE!
D15: 5 | E15: V | G15: 0 | H15: =INDEX([3]DataKontrak_BLU!$AN$5:$AN$104,MATCH(Realisasi_BLU!$G$1,id_kontrak,0)) -> 473782875 | I15: =INDEX(-[3]DataKontrak_BLU!$BB$5:$BB$104,MATCH(Realisasi_BLU!$G$1,id_kontrak,0)) -> 0 | K15: 0 | L15: =SUM($G15:$K15) -> 473782875 | M15: =SUMIFS(data_pembayaran_total_pembayaran,data_pembayaran_no_kontrak,Realisasi_BLU!$K$7,data_pembayaran_termin_kontrak,Realisasi_BLU!D15) -> #VALUE! | O15: =SUM(SUMIFS(data_pembayaran_jumlah_potongan1,data_pembayaran_no_kontrak,$K$7,data_pembayaran_akun_potongan1,"411211",data_pembayaran_termin_kontrak,$D15),SUMIFS(data_pembayaran_jumlah_potongan2,data_pembayaran_no_kontrak,$K$7,data_pembayaran_akun_potongan2,"411211",data_pembayaran_termin_kontrak,$D15),SUMIFS(data_pembayaran_jumlah_potongan3,data_pembayaran_no_kontrak,$K$7,data_pembayaran_akun_potongan3,"411211",data_pembayaran_termin_kontrak,$D15)) -> #VALUE! | P15: {=SUM(SUMIFS(data_pembayaran_jumlah_potongan1,data_pembayaran_no_kontrak,$K$7,data_pembayaran_akun_potongan1,{"411121";"411122";"411124"},data_pembayaran_termin_kontrak,$D15),SUMIFS(data_pembayaran_jumlah_potongan2,data_pembayaran_no_kontrak,$K$7,data_pembayaran_akun_potongan2,{"411121";"411122";"411124"},data_pembayaran_termin_kontrak,$D15),SUMIFS(data_pembayaran_jumlah_potongan3,data_pembayaran_no_kontrak,$K$7,data_pembayaran_akun_potongan3,{"411121";"411122";"411124"},data_pembayaran_termin_kontrak,$D15))} -> #VALUE!
D16: 6 | E16: VI | G16: 0 | H16: =INDEX([3]DataKontrak_BLU!$AO$5:$AO$104,MATCH(Realisasi_BLU!$G$1,id_kontrak,0)) -> 473782875 | I16: =INDEX(-[3]DataKontrak_BLU!$BC$5:$BC$104,MATCH(Realisasi_BLU!$G$1,id_kontrak,0)) -> 0 | K16: 0 | L16: =SUM($G16:$K16) -> 473782875 | M16: =SUMIFS(data_pembayaran_total_pembayaran,data_pembayaran_no_kontrak,Realisasi_BLU!$K$7,data_pembayaran_termin_kontrak,Realisasi_BLU!D16) -> #VALUE! | O16: =SUM(SUMIFS(data_pembayaran_jumlah_potongan1,data_pembayaran_no_kontrak,$K$7,data_pembayaran_akun_potongan1,"411211",data_pembayaran_termin_kontrak,$D16),SUMIFS(data_pembayaran_jumlah_potongan2,data_pembayaran_no_kontrak,$K$7,data_pembayaran_akun_potongan2,"411211",data_pembayaran_termin_kontrak,$D16),SUMIFS(data_pembayaran_jumlah_potongan3,data_pembayaran_no_kontrak,$K$7,data_pembayaran_akun_potongan3,"411211",data_pembayaran_termin_kontrak,$D16)) -> #VALUE! | P16: {=SUM(SUMIFS(data_pembayaran_jumlah_potongan1,data_pembayaran_no_kontrak,$K$7,data_pembayaran_akun_potongan1,{"411121";"411122";"411124"},data_pembayaran_termin_kontrak,$D16),SUMIFS(data_pembayaran_jumlah_potongan2,data_pembayaran_no_kontrak,$K$7,data_pembayaran_akun_potongan2,{"411121";"411122";"411124"},data_pembayaran_termin_kontrak,$D16),SUMIFS(data_pembayaran_jumlah_potongan3,data_pembayaran_no_kontrak,$K$7,data_pembayaran_akun_potongan3,{"411121";"411122";"411124"},data_pembayaran_termin_kontrak,$D16))} -> #VALUE!
D17: 7 | E17: VII | G17: 0 | H17: =INDEX([3]DataKontrak_BLU!$AP$5:$AP$104,MATCH(Realisasi_BLU!$G$1,id_kontrak,0)) -> 473782875 | I17: =INDEX(-[3]DataKontrak_BLU!$BD$5:$BD$104,MATCH(Realisasi_BLU!$G$1,id_kontrak,0)) -> 0 | K17: 0 | L17: =SUM($G17:$K17) -> 473782875 | M17: =SUMIFS(data_pembayaran_total_pembayaran,data_pembayaran_no_kontrak,Realisasi_BLU!$K$7,data_pembayaran_termin_kontrak,Realisasi_BLU!D17) -> #VALUE! | O17: =SUM(SUMIFS(data_pembayaran_jumlah_potongan1,data_pembayaran_no_kontrak,$K$7,data_pembayaran_akun_potongan1,"411211",data_pembayaran_termin_kontrak,$D17),SUMIFS(data_pembayaran_jumlah_potongan2,data_pembayaran_no_kontrak,$K$7,data_pembayaran_akun_potongan2,"411211",data_pembayaran_termin_kontrak,$D17),SUMIFS(data_pembayaran_jumlah_potongan3,data_pembayaran_no_kontrak,$K$7,data_pembayaran_akun_potongan3,"411211",data_pembayaran_termin_kontrak,$D17)) -> #VALUE! | P17: {=SUM(SUMIFS(data_pembayaran_jumlah_potongan1,data_pembayaran_no_kontrak,$K$7,data_pembayaran_akun_potongan1,{"411121";"411122";"411124"},data_pembayaran_termin_kontrak,$D17),SUMIFS(data_pembayaran_jumlah_potongan2,data_pembayaran_no_kontrak,$K$7,data_pembayaran_akun_potongan2,{"411121";"411122";"411124"},data_pembayaran_termin_kontrak,$D17),SUMIFS(data_pembayaran_jumlah_potongan3,data_pembayaran_no_kontrak,$K$7,data_pembayaran_akun_potongan3,{"411121";"411122";"411124"},data_pembayaran_termin_kontrak,$D17))} -> #VALUE!
D18: 8 | E18: VIII | G18: 0 | H18: =INDEX([3]DataKontrak_BLU!$AQ$5:$AQ$104,MATCH(Realisasi_BLU!$G$1,id_kontrak,0)) -> 473782875 | I18: =INDEX(-[3]DataKontrak_BLU!$BE$5:$BE$104,MATCH(Realisasi_BLU!$G$1,id_kontrak,0)) -> 0 | K18: 0 | L18: =SUM($G18:$K18) -> 473782875 | M18: =SUMIFS(data_pembayaran_total_pembayaran,data_pembayaran_no_kontrak,Realisasi_BLU!$K$7,data_pembayaran_termin_kontrak,Realisasi_BLU!D18) -> #VALUE! | O18: =SUM(SUMIFS(data_pembayaran_jumlah_potongan1,data_pembayaran_no_kontrak,$K$7,data_pembayaran_akun_potongan1,"411211",data_pembayaran_termin_kontrak,$D18),SUMIFS(data_pembayaran_jumlah_potongan2,data_pembayaran_no_kontrak,$K$7,data_pembayaran_akun_potongan2,"411211",data_pembayaran_termin_kontrak,$D18),SUMIFS(data_pembayaran_jumlah_potongan3,data_pembayaran_no_kontrak,$K$7,data_pembayaran_akun_potongan3,"411211",data_pembayaran_termin_kontrak,$D18)) -> #VALUE! | P18: {=SUM(SUMIFS(data_pembayaran_jumlah_potongan1,data_pembayaran_no_kontrak,$K$7,data_pembayaran_akun_potongan1,{"411121";"411122";"411124"},data_pembayaran_termin_kontrak,$D18),SUMIFS(data_pembayaran_jumlah_potongan2,data_pembayaran_no_kontrak,$K$7,data_pembayaran_akun_potongan2,{"411121";"411122";"411124"},data_pembayaran_termin_kontrak,$D18),SUMIFS(data_pembayaran_jumlah_potongan3,data_pembayaran_no_kontrak,$K$7,data_pembayaran_akun_potongan3,{"411121";"411122";"411124"},data_pembayaran_termin_kontrak,$D18))} -> #VALUE!
D19: 9 | E19: IX | G19: 0 | H19: =INDEX([3]DataKontrak_BLU!$AR$5:$AR$104,MATCH(Realisasi_BLU!$G$1,id_kontrak,0)) -> 473782875 | I19: =INDEX(-[3]DataKontrak_BLU!$BF$5:$BF$104,MATCH(Realisasi_BLU!$G$1,id_kontrak,0)) -> 0 | K19: 0 | L19: =SUM($G19:$K19) -> 473782875 | M19: =SUMIFS(data_pembayaran_total_pembayaran,data_pembayaran_no_kontrak,Realisasi_BLU!$K$7,data_pembayaran_termin_kontrak,Realisasi_BLU!D19) -> #VALUE! | O19: =SUM(SUMIFS(data_pembayaran_jumlah_potongan1,data_pembayaran_no_kontrak,$K$7,data_pembayaran_akun_potongan1,"411211",data_pembayaran_termin_kontrak,$D19),SUMIFS(data_pembayaran_jumlah_potongan2,data_pembayaran_no_kontrak,$K$7,data_pembayaran_akun_potongan2,"411211",data_pembayaran_termin_kontrak,$D19),SUMIFS(data_pembayaran_jumlah_potongan3,data_pembayaran_no_kontrak,$K$7,data_pembayaran_akun_potongan3,"411211",data_pembayaran_termin_kontrak,$D19)) -> #VALUE! | P19: {=SUM(SUMIFS(data_pembayaran_jumlah_potongan1,data_pembayaran_no_kontrak,$K$7,data_pembayaran_akun_potongan1,{"411121";"411122";"411124"},data_pembayaran_termin_kontrak,$D19),SUMIFS(data_pembayaran_jumlah_potongan2,data_pembayaran_no_kontrak,$K$7,data_pembayaran_akun_potongan2,{"411121";"411122";"411124"},data_pembayaran_termin_kontrak,$D19),SUMIFS(data_pembayaran_jumlah_potongan3,data_pembayaran_no_kontrak,$K$7,data_pembayaran_akun_potongan3,{"411121";"411122";"411124"},data_pembayaran_termin_kontrak,$D19))} -> #VALUE!
D20: 10 | E20: X | G20: 0 | H20: =INDEX([3]DataKontrak_BLU!$AS$5:$AS$104,MATCH(Realisasi_BLU!$G$1,id_kontrak,0)) -> 473782875 | I20: =INDEX(-[3]DataKontrak_BLU!$BG$5:$BG$104,MATCH(Realisasi_BLU!$G$1,id_kontrak,0)) -> 0 | K20: 0 | L20: =SUM($G20:$K20) -> 473782875 | M20: =SUMIFS(data_pembayaran_total_pembayaran,data_pembayaran_no_kontrak,Realisasi_BLU!$K$7,data_pembayaran_termin_kontrak,Realisasi_BLU!D20) -> #VALUE! | O20: =SUM(SUMIFS(data_pembayaran_jumlah_potongan1,data_pembayaran_no_kontrak,$K$7,data_pembayaran_akun_potongan1,"411211",data_pembayaran_termin_kontrak,$D20),SUMIFS(data_pembayaran_jumlah_potongan2,data_pembayaran_no_kontrak,$K$7,data_pembayaran_akun_potongan2,"411211",data_pembayaran_termin_kontrak,$D20),SUMIFS(data_pembayaran_jumlah_potongan3,data_pembayaran_no_kontrak,$K$7,data_pembayaran_akun_potongan3,"411211",data_pembayaran_termin_kontrak,$D20)) -> #VALUE! | P20: {=SUM(SUMIFS(data_pembayaran_jumlah_potongan1,data_pembayaran_no_kontrak,$K$7,data_pembayaran_akun_potongan1,{"411121";"411122";"411124"},data_pembayaran_termin_kontrak,$D20),SUMIFS(data_pembayaran_jumlah_potongan2,data_pembayaran_no_kontrak,$K$7,data_pembayaran_akun_potongan2,{"411121";"411122";"411124"},data_pembayaran_termin_kontrak,$D20),SUMIFS(data_pembayaran_jumlah_potongan3,data_pembayaran_no_kontrak,$K$7,data_pembayaran_akun_potongan3,{"411121";"411122";"411124"},data_pembayaran_termin_kontrak,$D20))} -> #VALUE!
D21: 11 | E21: XI | G21: 0 | H21: =INDEX([3]DataKontrak_BLU!$AT$5:$AT$104,MATCH(Realisasi_BLU!$G$1,id_kontrak,0)) -> 473782875 | I21: =INDEX(-[3]DataKontrak_BLU!$BH$5:$BH$104,MATCH(Realisasi_BLU!$G$1,id_kontrak,0)) -> 0 | K21: 0 | L21: =SUM($G21:$K21) -> 473782875 | M21: =SUMIFS(data_pembayaran_total_pembayaran,data_pembayaran_no_kontrak,Realisasi_BLU!$K$7,data_pembayaran_termin_kontrak,Realisasi_BLU!D21) -> #VALUE! | O21: =SUM(SUMIFS(data_pembayaran_jumlah_potongan1,data_pembayaran_no_kontrak,$K$7,data_pembayaran_akun_potongan1,"411211",data_pembayaran_termin_kontrak,$D21),SUMIFS(data_pembayaran_jumlah_potongan2,data_pembayaran_no_kontrak,$K$7,data_pembayaran_akun_potongan2,"411211",data_pembayaran_termin_kontrak,$D21),SUMIFS(data_pembayaran_jumlah_potongan3,data_pembayaran_no_kontrak,$K$7,data_pembayaran_akun_potongan3,"411211",data_pembayaran_termin_kontrak,$D21)) -> #VALUE! | P21: {=SUM(SUMIFS(data_pembayaran_jumlah_potongan1,data_pembayaran_no_kontrak,$K$7,data_pembayaran_akun_potongan1,{"411121";"411122";"411124"},data_pembayaran_termin_kontrak,$D21),SUMIFS(data_pembayaran_jumlah_potongan2,data_pembayaran_no_kontrak,$K$7,data_pembayaran_akun_potongan2,{"411121";"411122";"411124"},data_pembayaran_termin_kontrak,$D21),SUMIFS(data_pembayaran_jumlah_potongan3,data_pembayaran_no_kontrak,$K$7,data_pembayaran_akun_potongan3,{"411121";"411122";"411124"},data_pembayaran_termin_kontrak,$D21))} -> #VALUE!
D22: 12 | E22: XII | G22: 0 | H22: =INDEX([3]DataKontrak_BLU!$AU$5:$AU$104,MATCH(Realisasi_BLU!$G$1,id_kontrak,0)) -> 473782875 | I22: =INDEX(-[3]DataKontrak_BLU!$BI$5:$BI$104,MATCH(Realisasi_BLU!$G$1,id_kontrak,0)) -> 0 | K22: 0 | L22: =SUM($G22:$K22) -> 473782875 | M22: =SUMIFS(data_pembayaran_total_pembayaran,data_pembayaran_no_kontrak,Realisasi_BLU!$K$7,data_pembayaran_termin_kontrak,Realisasi_BLU!D22) -> #VALUE! | O22: =SUM(SUMIFS(data_pembayaran_jumlah_potongan1,data_pembayaran_no_kontrak,$K$7,data_pembayaran_akun_potongan1,"411211",data_pembayaran_termin_kontrak,$D22),SUMIFS(data_pembayaran_jumlah_potongan2,data_pembayaran_no_kontrak,$K$7,data_pembayaran_akun_potongan2,"411211",data_pembayaran_termin_kontrak,$D22),SUMIFS(data_pembayaran_jumlah_potongan3,data_pembayaran_no_kontrak,$K$7,data_pembayaran_akun_potongan3,"411211",data_pembayaran_termin_kontrak,$D22)) -> #VALUE! | P22: {=SUM(SUMIFS(data_pembayaran_jumlah_potongan1,data_pembayaran_no_kontrak,$K$7,data_pembayaran_akun_potongan1,{"411121";"411122";"411124"},data_pembayaran_termin_kontrak,$D22),SUMIFS(data_pembayaran_jumlah_potongan2,data_pembayaran_no_kontrak,$K$7,data_pembayaran_akun_potongan2,{"411121";"411122";"411124"},data_pembayaran_termin_kontrak,$D22),SUMIFS(data_pembayaran_jumlah_potongan3,data_pembayaran_no_kontrak,$K$7,data_pembayaran_akun_potongan3,{"411121";"411122";"411124"},data_pembayaran_termin_kontrak,$D22))} -> #VALUE!
D23: 13 | E23: XIII | G23: 0 | H23: =INDEX([3]DataKontrak_BLU!$AV$5:$AV$104,MATCH(Realisasi_BLU!$G$1,id_kontrak,0)) -> 0 | I23: =INDEX(-[3]DataKontrak_BLU!$BJ$5:$BJ$104,MATCH(Realisasi_BLU!$G$1,id_kontrak,0)) -> 0 | K23: 0 | L23: =SUM($G23:$K23) -> 0 | M23: =SUMIFS(data_pembayaran_total_pembayaran,data_pembayaran_no_kontrak,Realisasi_BLU!$K$7,data_pembayaran_termin_kontrak,Realisasi_BLU!D23) -> #VALUE! | O23: =SUM(SUMIFS(data_pembayaran_jumlah_potongan1,data_pembayaran_no_kontrak,$K$7,data_pembayaran_akun_potongan1,"411211",data_pembayaran_termin_kontrak,$D23),SUMIFS(data_pembayaran_jumlah_potongan2,data_pembayaran_no_kontrak,$K$7,data_pembayaran_akun_potongan2,"411211",data_pembayaran_termin_kontrak,$D23),SUMIFS(data_pembayaran_jumlah_potongan3,data_pembayaran_no_kontrak,$K$7,data_pembayaran_akun_potongan3,"411211",data_pembayaran_termin_kontrak,$D23)) -> #VALUE! | P23: {=SUM(SUMIFS(data_pembayaran_jumlah_potongan1,data_pembayaran_no_kontrak,$K$7,data_pembayaran_akun_potongan1,{"411121";"411122";"411124"},data_pembayaran_termin_kontrak,$D23),SUMIFS(data_pembayaran_jumlah_potongan2,data_pembayaran_no_kontrak,$K$7,data_pembayaran_akun_potongan2,{"411121";"411122";"411124"},data_pembayaran_termin_kontrak,$D23),SUMIFS(data_pembayaran_jumlah_potongan3,data_pembayaran_no_kontrak,$K$7,data_pembayaran_akun_potongan3,{"411121";"411122";"411124"},data_pembayaran_termin_kontrak,$D23))} -> #VALUE!
D24: 14 | E24: XIV | G24: 0 | H24: =INDEX([3]DataKontrak_BLU!$AW$5:$AW$104,MATCH(Realisasi_BLU!$G$1,id_kontrak,0)) -> 0 | I24: =INDEX(-[3]DataKontrak_BLU!$BK$5:$BK$104,MATCH(Realisasi_BLU!$G$1,id_kontrak,0)) -> 0 | K24: 0 | L24: =SUM($G24:$K24) -> 0 | M24: =SUMIFS(data_pembayaran_total_pembayaran,data_pembayaran_no_kontrak,Realisasi_BLU!$K$7,data_pembayaran_termin_kontrak,Realisasi_BLU!D24) -> #VALUE! | O24: =SUM(SUMIFS(data_pembayaran_jumlah_potongan1,data_pembayaran_no_kontrak,$K$7,data_pembayaran_akun_potongan1,"411211",data_pembayaran_termin_kontrak,$D24),SUMIFS(data_pembayaran_jumlah_potongan2,data_pembayaran_no_kontrak,$K$7,data_pembayaran_akun_potongan2,"411211",data_pembayaran_termin_kontrak,$D24),SUMIFS(data_pembayaran_jumlah_potongan3,data_pembayaran_no_kontrak,$K$7,data_pembayaran_akun_potongan3,"411211",data_pembayaran_termin_kontrak,$D24)) -> #VALUE! | P24: {=SUM(SUMIFS(data_pembayaran_jumlah_potongan1,data_pembayaran_no_kontrak,$K$7,data_pembayaran_akun_potongan1,{"411121";"411122";"411124"},data_pembayaran_termin_kontrak,$D24),SUMIFS(data_pembayaran_jumlah_potongan2,data_pembayaran_no_kontrak,$K$7,data_pembayaran_akun_potongan2,{"411121";"411122";"411124"},data_pembayaran_termin_kontrak,$D24),SUMIFS(data_pembayaran_jumlah_potongan3,data_pembayaran_no_kontrak,$K$7,data_pembayaran_akun_potongan3,{"411121";"411122";"411124"},data_pembayaran_termin_kontrak,$D24))} -> #VALUE!
D25: 15 | E25: XV | G25: 0 | H25: =INDEX([3]DataKontrak_BLU!$AX$5:$AX$104,MATCH(Realisasi_BLU!$G$1,id_kontrak,0)) -> 0 | I25: =INDEX(-[3]DataKontrak_BLU!$BL$5:$BL$104,MATCH(Realisasi_BLU!$G$1,id_kontrak,0)) -> 0 | K25: 0 | L25: =SUM($G25:$K25) -> 0 | M25: =SUMIFS(data_pembayaran_total_pembayaran,data_pembayaran_no_kontrak,Realisasi_BLU!$K$7,data_pembayaran_termin_kontrak,Realisasi_BLU!D25) -> #VALUE! | O25: =SUM(SUMIFS(data_pembayaran_jumlah_potongan1,data_pembayaran_no_kontrak,$K$7,data_pembayaran_akun_potongan1,"411211",data_pembayaran_termin_kontrak,$D25),SUMIFS(data_pembayaran_jumlah_potongan2,data_pembayaran_no_kontrak,$K$7,data_pembayaran_akun_potongan2,"411211",data_pembayaran_termin_kontrak,$D25),SUMIFS(data_pembayaran_jumlah_potongan3,data_pembayaran_no_kontrak,$K$7,data_pembayaran_akun_potongan3,"411211",data_pembayaran_termin_kontrak,$D25)) -> #VALUE! | P25: {=SUM(SUMIFS(data_pembayaran_jumlah_potongan1,data_pembayaran_no_kontrak,$K$7,data_pembayaran_akun_potongan1,{"411121";"411122";"411124"},data_pembayaran_termin_kontrak,$D25),SUMIFS(data_pembayaran_jumlah_potongan2,data_pembayaran_no_kontrak,$K$7,data_pembayaran_akun_potongan2,{"411121";"411122";"411124"},data_pembayaran_termin_kontrak,$D25),SUMIFS(data_pembayaran_jumlah_potongan3,data_pembayaran_no_kontrak,$K$7,data_pembayaran_akun_potongan3,{"411121";"411122";"411124"},data_pembayaran_termin_kontrak,$D25))} -> #VALUE!
E26: TOTAL | G26: =SUBTOTAL(9,G$11:G$25) -> 0 | H26: =SUBTOTAL(9,H$11:H$25) -> 5685394500 | I26: =SUBTOTAL(9,I$11:I$25) -> 0 | K26: =SUBTOTAL(9,K$11:K$25) -> 0 | L26: =SUBTOTAL(9,L$11:L$25) -> 5685394500 | M26: =SUBTOTAL(9,M$11:M$25) -> #VALUE! | N26: =SUBTOTAL(9,N$11:N$25) -> 0 | O26: =SUBTOTAL(9,O$11:O$25) -> #VALUE! | P26: =SUBTOTAL(9,P$11:P$25) -> #VALUE!

Sheet ResumeKontrak_BLU
E1: ID | F1: 003-0-PL.107/0002/PPK.BB/APTP/2026
E2: RINGKASAN KONTRAK
E4: Untuk kegiatan dengan sumber dana Badan Layanan Umum
E7: 1. | F7: Nomor dan Tanggal DIPA | G7: : | H7: DIPA-022.05.2.288745/2025 02-12-2024
E8: 2. | F8: MAK | G8: : | H8: =INDEX([3]DataKontrak_BLU!BM$5:BM$304,MATCH(ResumeKontrak_BLU!$F$1,id_kontrak,0)) -> WA.4611.EBA.962.051.A.525119.00002
E9: 3. | F9: Nomor dan Tanggal SPK/Kontrak | G9: : | H9: =CONCATENATE(INDEX([3]DataKontrak_BLU!G$5:G$304,MATCH(ResumeKontrak_BLU!$F$1,id_kontrak,0))," ",TEXT(INDEX([3]DataKontrak_BLU!H$5:H$304,MATCH(ResumeKontrak_BLU!$F$1,id_kontrak,0)),"dd-mm-yyyy")) -> PL.107/0002/PPK.BB/APTP/2026 00-01-1900
E10: 4. | F10: Nama Perusahaan | G10: : | H10: =INDEX([3]DataKontrak_BLU!M$5:M$304,MATCH(ResumeKontrak_BLU!$F$1,id_kontrak,0)) -> PT. GARUDA TAWAKAL ABADI
E11: 5. | F11: Alamat Perusahaan | G11: : | H11: =INDEX(Supplier!$D$2:$D$88,MATCH(ResumeKontrak_BLU!$H$10,Supplier!$B$2:$B$88,0)) -> Jl. Griyo Mapan Sentosa EA1 No.2B RT.042 RW.005
E14: 6. | F14: Nilai Kontrak | G14: : | H14: =INDEX([3]DataKontrak_BLU!P$5:P$304,MATCH(ResumeKontrak_BLU!$F$1,id_kontrak,0)) -> 6368521200
E15: 7. | F15: Uraian dan Volume Pekerjaan | G15: : | H15: =INDEX([3]DataKontrak_BLU!L$5:L$304,MATCH(ResumeKontrak_BLU!$F$1,id_kontrak,0)) -> PENGADAAN JASA OUTSOURCHING PENGAMANAN BANDARA (PERSONIL AVSEC) 1 PAKET
E19: 8. | F19: Cara Pembayaran | G19: : | H19: =INDEX([3]DataKontrak_BLU!R$5:R$304,MATCH(ResumeKontrak_BLU!$F$1,id_kontrak,0)) -> Termin
E20: 9. | F20: Jangka Waktu Pelaksanaan | G20: : | H20: =CONCATENATE(INDEX([3]DataKontrak_BLU!T$5:T$304,MATCH(ResumeKontrak_BLU!$F$1,id_kontrak,0))," Hari") -> 365 Hari
E21: 10. | F21: Tanggal Penyelesaian Pekerjaan | G21: : | H21: =TEXT(INDEX([3]DataKontrak_BLU!V$5:V$304,MATCH(ResumeKontrak_BLU!$F$1,id_kontrak,0)),"dd mmmm yyyy") -> 31 December 2026
E22: 11. | F22: Jangka Waktu Pemeliharaan | G22: : | H22: =CONCATENATE(INDEX([3]DataKontrak_BLU!W$5:W$304,MATCH(ResumeKontrak_BLU!$F$1,id_kontrak,0))," Hari") -> Hari
E23: 12. | F23: Ketentuan Sanksi | G23: : | H23: =IF(INDEX([3]DataKontrak_BLU!Z$5:Z$304,MATCH(ResumeKontrak_BLU!$F$1,id_kontrak,0))=0,"-",INDEX([3]DataKontrak_BLU!Z$5:Z$104,MATCH(ResumeKontrak_BLU!$F$1,id_kontrak,0))) -> -
E27: Catatan : | J27: ="Samarinda, "&TEXT(NOW(),"dd-mm-yyyy") -> Samarinda, 01-04-2026
E28: Apabila terjadi addendum kontrak, data kontrak agar disesuaikan dengan perubahannya | J28: a.n. Kuasa Pengguna Anggaran
J29: Pejabat Pembuat Komitmen
J34: =INDEX([3]DataKontrak_BLU!BN$5:BN$304,MATCH(ResumeKontrak_BLU!$F$1,id_kontrak,0)) -> Gunawan
J35: ="NIP "&DataPejabat!C3 -> NIP 198411052007121001

Sheet DataPembayaran_BLU
A1: No | B1: Tanggal_SPM | C1: Nomor_SPM | D1: Jenis_Tagihan | E1: Cara_Bayar | F1: Supplier | G1: Uraian | H1: Kontrak | I1: Tanggal_Kontrak | J1: Termin | K1: COA | L1: Jumlah_Pembayaran | M1: Akun_Potongan1 | N1: Jumlah_Potongan1 | O1: Akun_Potongan2 | P1: Jumlah_Potongan2 | Q1: Akun_Potongan3 | R1: Jumlah_Potongan3 | S1: Nomor_BAST | T1: Tanggal_BAST | U1: Jenis_Belanja | V1: PPK | W1: Status SP3B
A2: 1 | B2: 46051 | C2: SPM-BLU/APTP-2026/0001 | D2: NON REMUNERASI | E2: SP2D BLU - TRF | F2: CV. GARUDA KARYA BERSAMA | G2: Pembayaran Belanja Barang Pekerjaan Pemotongan Rumput Sisi Udara Tahap I : 1 (Satu) Paket | H2: PL.107/0007/PPK.BB/APTP/2026 | I2: 46027 | K2: =Pagu_BLU!I17 -> GA.4647.CDE.001.051.A.525114.00002 | L2: 196697855 | M2: 411211 | N2: 19492580 | O2: 411124 | P2: 3544106 | S2: PL.108/0024/PPK.BB/APTP/2026 | T2: 46047 | U2: =IF(ISBLANK(K2),"",IF(MID(K2,23,2)="52","Belanja Barang","Belanja Modal")) -> Belanja Barang | V2: GUNAWAN
A3: 2 | B3: 46051 | C3: SPM-BLU/APTP-2026/0002 | D3: NON REMUNERASI | E3: SP2D BLU - TRF | F3: CV. GUNA AKHLAK SUKSES | G3: Pembayaran Belanja Barang Pengadaan Obat Air | H3: PL.107/0011/PPK.BB/APTP/2026 | I3: 46027 | K3: =Pagu_BLU!I38 -> GA.4647.CDE.001.054.B.525114.00002 | L3: 194986485 | M3: 411211 | N3: 19322985 | O3: 411124 | P3: 3513270 | S3: PL.108/0017/PPK.BB/APTP/2026 | T3: 46034 | U3: =IF(ISBLANK(K3),"",IF(MID(K3,23,2)="52","Belanja Barang","Belanja Modal")) -> Belanja Barang | V3: GUNAWAN
A4: 3 | B4: 46051 | C4: SPM-BLU/APTP-2026/0003 | D4: NON REMUNERASI | E4: SP2D BLU - TRF | F4: PT. ANGKASA JAYA SERVIS | G4: Pembayaran Belanja Barang Pemeliharaan Fasilitas Sisi udara | K4: =Pagu_BLU!I21 -> GA.4647.CDE.001.051.A.525114.00006 | L4: 35964000 | M4: 411211 | N4: 3564000 | O4: 411124 | P4: 648000 | S4: PL.108/0027/PPK.BB/APTP/2026 | T4: 46028 | U4: =IF(ISBLANK(K4),"",IF(MID(K4,23,2)="52","Belanja Barang","Belanja Modal")) -> Belanja Barang | V4: GUNAWAN
A5: 4 | B5: 46051 | C5: SPM-BLU/APTP-2026/0004 | D5: NON REMUNERASI | E5: SP2D BLU - TRF | F5: CV. GUNA AKHLAK SUKSES | G5: Pembayaran Belanja Barang Pemeliharaan Sistem Tata Udara | K5: =Pagu_BLU!I40 -> GA.4647.CDE.001.054.B.525114.00004 | L5: 26640000 | M5: 411211 | N5: 2640000 | O5: 411124 | P5: 480000 | S5: PL.108/0033/PPK.BB/APTP/2026 | T5: 46028 | U5: =IF(ISBLANK(K5),"",IF(MID(K5,23,2)="52","Belanja Barang","Belanja Modal")) -> Belanja Barang | V5: GUNAWAN
A6: 5 | B6: 46051 | C6: SPM-BLU/APTP-2026/0005 | D6: NON REMUNERASI | E6: SP2D BLU - TRF | F6: CV. GUNA AKHLAK SUKSES | G6: Pembayaran Belanja Barang Pemeliharaan Sistem Air Bersih | K6: =Pagu_BLU!I38 -> GA.4647.CDE.001.054.B.525114.00002 | L6: 10989000 | M6: 411211 | N6: 1089000 | O6: 411124 | P6: 198000 | S6: PL.108/0036/PPK.BB/APTP/2026 | T6: 46043 | U6: =IF(ISBLANK(K6),"",IF(MID(K6,23,2)="52","Belanja Barang","Belanja Modal")) -> Belanja Barang | V6: GUNAWAN
A7: 6 | B7: 46051 | C7: SPM-BLU/APTP-2026/0006 | D7: NON REMUNERASI | E7: SP2D BLU - TRF | F7: PT. ANGKASA JAYA SERVIS | G7: Pembayaran Belanja Barang Pengelolaan Sistem Limbah | K7: =Pagu_BLU!I39 -> GA.4647.CDE.001.054.B.525114.00003 | L7: 21867000 | M7: 411211 | N7: 2167000 | O7: 411124 | P7: 394000 | S7: PL.108/0030/PPK.BB/APTP/2026 | T7: 46045 | U7: =IF(ISBLANK(K7),"",IF(MID(K7,23,2)="52","Belanja Barang","Belanja Modal")) -> Belanja Barang | V7: GUNAWAN
A8: 7 | B8: 46051 | C8: SPM-BLU/APTP-2026/0007 | D8: NON REMUNERASI | E8: SP2D BLU - TRF | F8: CV. GUNA AKHLAK SUKSES | G8: Pembayaran Belanja Barang Perbaikan Sofa Disabilitas | K8: =Pagu_BLU!I70 -> WA.4611.EBA.962.052.E.525112.00005 | L8: 35520000 | M8: 411211 | N8: 3520000 | O8: 411124 | P8: 640000 | S8: PL.108/0039/PPK.BB/APTP/2026 | T8: 46043 | U8: =IF(ISBLANK(K8),"",IF(MID(K8,23,2)="52","Belanja Barang","Belanja Modal")) -> Belanja Barang | V8: GUNAWAN
A9: 8 | B9: 46051 | C9: SPM-BLU/APTP-2026/0008 | D9: NON REMUNERASI | E9: SP2D BLU - TRF | F9: PT. ANGKASA JAYA SERVIS | G9: Pembayaran Belanja Barang Perbaikan Conveyor Checkin | K9: =Pagu_BLU!I41 -> GA.4647.CDE.001.054.B.525114.00005 | L9: 4440000 | M9: 411211 | N9: 440000 | O9: 411124 | P9: 80000 | S9: PL.108/0042/PPK.BB/APTP/2026 | T9: 46049 | U9: =IF(ISBLANK(K9),"",IF(MID(K9,23,2)="52","Belanja Barang","Belanja Modal")) -> Belanja Barang | V9: GUNAWAN
A10: 9 | B10: 46051 | C10: SPM-BLU/APTP-2026/0009 | D10: NON REMUNERASI | E10: SP2D BLU - TRF | F10: POLITEKNIK PENERBANGAN PALEMBANG | G10: Pembayaran Belanja Pelatihan Basic PK Angkatan XLVI | K10: =Pagu_BLU!I108 -> WA.4613.EBA.960.053.A.525112.00005 | L10: 25000000 | S10: INV.004/D/I/2028 | T10: 46052 | U10: =IF(ISBLANK(K10),"",IF(MID(K10,23,2)="52","Belanja Barang","Belanja Modal")) -> Belanja Barang | V10: GUNAWAN
A11: 10 | B11: 46057 | C11: SPM-BLU/APTP-2026/0010 | D11: NON REMUNERASI | E11: SP2D BLU - TRF | F11: PT. INTERCIPTA JASA INDONESIA | G11: Pembayaran Belanja Barang Pengadaan Jasa Kebersihan Terminal dan Pemeliharaan Landscape Bandar udara Paket 1 Periode 01-31 Januari 2026 | H11: PL.107/0001/PPK.BB/APTP/2026 | I11: 46023 | K11: =Pagu_BLU!I51 -> WA.4611.EBA.962.051.A.525119.00001 | L11: 477943459 | M11: 411211 | N11: 47363766 | O11: 411124 | P11: 8611594 | S11: PL.108/0055/PPK.BB/APTP/2026 | T11: 46055 | U11: =IF(ISBLANK(K11),"",IF(MID(K11,23,2)="52","Belanja Barang","Belanja Modal")) -> Belanja Barang | V11: GUNAWAN
A12: 11 | B12: 46057 | C12: SPM-BLU/APTP-2026/0011 | D12: NON REMUNERASI | E12: SP2D BLU - TRF | F12: PT. GARUDA TAWAKAL ABADI | G12: Pembayaran Belanja Barang Pengadaan Jasa Outsourcing Pengamanan Bandar Udara (Personil Avsec) 1 Paket Periode Januari | H12: PL.107/0019/PPK.BB/APTP/2026 | I12: 46023 | K12: =Pagu_BLU!I52 -> WA.4611.EBA.962.051.A.525119.00002 | L12: 538468056 | M12: 411211 | N12: 53361699 | O12: 411124 | P12: 9702127 | S12: PL.108/0051/PPK.BB/APTP/2026 | T12: 46055 | U12: =IF(ISBLANK(K12),"",IF(MID(K12,23,2)="52","Belanja Barang","Belanja Modal")) -> Belanja Barang | V12: GUNAWAN
A13: 12 | B13: 46057 | C13: SPM-BLU/APTP-2026/0012 | D13: NON REMUNERASI | E13: SP2D BLU - TRF | F13: PT. ANGKASA JAYA SERVIS | G13: Pembayaran Belanja Barang Jasa Pengangkutan Sampah Periode Januari | K13: =Pagu_BLU!I69 -> WA.4611.EBA.962.052.E.525112.00004 | L13: 16000000 | M13: 411211 | N13: 1585586 | O13: 411124 | P13: 288288 | S13: PL.108/0046/PPK.BB/APTP/2026 | T13: 46055 | U13: =IF(ISBLANK(K13),"",IF(MID(K13,23,2)="52","Belanja Barang","Belanja Modal")) -> Belanja Barang | V13: GUNAWAN
A14: 13 | B14: 46057 | C14: SPM-BLU/APTP-2026/0013 | D14: NON REMUNERASI | E14: SP2D BLU - TRF | F14: CV. GUNA AKHLAK SUKSES | G14: Pembayaran Belanja Barang Pemeliharaan Ducting Return dan AHU Return | K14: =Pagu_BLU!I40 -> GA.4647.CDE.001.054.B.525114.00004 | L14: 38037000 | M14: 411211 | N14: 3773000 | O14: 411124 | P14: 686000 | S14: PL.108/0049/PPK.BB/APTP/2026 | T14: 46055 | U14: =IF(ISBLANK(K14),"",IF(MID(K14,23,2)="52","Belanja Barang","Belanja Modal")) -> Belanja Barang | V14: GUNAWAN
A15: 14 | B15: 46057 | C15: SPM-BLU/APTP-2026/0014 | D15: NON REMUNERASI | E15: SP2D BLU - TRF | F15: PT. ANGKASA JAYA SERVIS | G15: Pembayaran Belanja Barang Suku Cadang Listrik Bandara | K15: =Pagu_BLU!I33 -> GA.4647.CDE.001.054.A.525112.00002 | L15: 44300100 | M15: 411211 | N15: 4390100 | O15: 411122 | P15: 598650 | S15: PL.108/0065/PPK.BB/APTP/2026 | T15: 46056 | U15: =IF(ISBLANK(K15),"",IF(MID(K15,23,2)="52","Belanja Barang","Belanja Modal")) -> Belanja Barang | V15: GUNAWAN
A16: 15 | B16: 46057 | C16: SPM-BLU/APTP-2026/0015 | D16: NON REMUNERASI | E16: SP2D BLU - TRF | F16: PT. ANGKASA JAYA SERVIS | G16: Pembayaran Belanja Barang Suku Cadang Listrik Bandara Tahap II | K16: =Pagu_BLU!I33 -> GA.4647.CDE.001.054.A.525112.00002 | L16: 49891725 | M16: 411211 | N16: 4944225 | O16: 411122 | P16: 674213 | S16: PL.108/0068/PPK.BB/APTP/2026 | T16: 46056 | U16: =IF(ISBLANK(K16),"",IF(MID(K16,23,2)="52","Belanja Barang","Belanja Modal")) -> Belanja Barang | V16: GUNAWAN
A17: 16 | B17: 46057 | C17: SPM-BLU/APTP-2026/0016 | D17: NON REMUNERASI | E17: SP2D BLU - TRF | F17: PT. ANGKASA JAYA SERVIS | G17: Pembayaran Belanja Barang Suku Cadang Peralatan Elektronika | K17: =Pagu_BLU!I32 -> GA.4647.CDE.001.054.A.525112.00001 | L17: 46762080 | M17: 411211 | N17: 4634080 | O17: 411122 | P17: 631920 | S17: PL.108/0086/PPK.BB/APTP/2026 | T17: 46056 | U17: =IF(ISBLANK(K17),"",IF(MID(K17,23,2)="52","Belanja Barang","Belanja Modal")) -> Belanja Barang | V17: GUNAWAN
A18: 17 | B18: 46063 | C18: SPM-BLU/APTP-2026/0017 | D18: NON REMUNERASI | E18: SP2D BLU - TRF | F18: PARA PEGAWAI KANTOR UPBU AJI PANGERAN TUMENGGUNG PRANOTO | G18: Belanja Barang Perjalanan Dinas Pegawai - Tiket | K18: =Pagu_BLU!I82 -> WA.4611.EBD.001.056.B.525115.00004 | L18: 15396843 | S18: KU.201/0784/APTP/2026 | T18: 46055 | U18: =IF(ISBLANK(K18),"",IF(MID(K18,23,2)="52","Belanja Barang","Belanja Modal")) -> Belanja Barang | V18: GUNAWAN
A19: 18 | B19: 46063 | C19: SPM-BLU/APTP-2026/0018 | D19: NON REMUNERASI | E19: SP2D BLU - TRF | F19: PARA PEGAWAI KANTOR UPBU AJI PANGERAN TUMENGGUNG PRANOTO | G19: Belanja Barang Perjalanan Dinas Pegawai - Taxi | K19: =Pagu_BLU!I80 -> WA.4611.EBD.001.056.B.525115.00002 | L19: 2674500 | S19: KU.201/0784/APTP/2026 | T19: 46055 | U19: =IF(ISBLANK(K19),"",IF(MID(K19,23,2)="52","Belanja Barang","Belanja Modal")) -> Belanja Barang | V19: GUNAWAN
A20: 19 | B20: 46063 | C20: SPM-BLU/APTP-2026/0019 | D20: NON REMUNERASI | E20: SP2D BLU - TRF | F20: PARA PEGAWAI KANTOR UPBU AJI PANGERAN TUMENGGUNG PRANOTO | G20: Belanja Barang Perjalanan Dinas Pegawai - Hotel | K20: =Pagu_BLU!I81 -> WA.4611.EBD.001.056.B.525115.00003 | L20: 2695001 | S20: KU.201/0784/APTP/2026 | T20: 46055 | U20: =IF(ISBLANK(K20),"",IF(MID(K20,23,2)="52","Belanja Barang","Belanja Modal")) -> Belanja Barang | V20: GUNAWAN
A21: 20 | B21: 46063 | C21: SPM-BLU/APTP-2026/0020 | D21: NON REMUNERASI | E21: SP2D BLU - TRF | F21: PARA PEGAWAI KANTOR UPBU AJI PANGERAN TUMENGGUNG PRANOTO | G21: Belanja Barang Perjalanan Dinas Pegawai - Uang Harian | K21: =Pagu_BLU!I79 -> WA.4611.EBD.001.056.B.525115.00001 | L21: 5860000 | S21: KU.201/0784/APTP/2026 | T21: 46055 | U21: =IF(ISBLANK(K21),"",IF(MID(K21,23,2)="52","Belanja Barang","Belanja Modal")) -> Belanja Barang | V21: GUNAWAN
A22: 21 | B22: 46066 | C22: SPM-BLU/APTP-2026/0021 | D22: NON REMUNERASI | E22: SP2D BLU - TRF | F22: PARA ANGGOTA TNI POLRI | G22: Pembayaran Belanja Barang kegiatan honorarium pengamanan objek vital bandara Periode Januari 2026 | K22: =Pagu_BLU!I42 -> GA.4647.CDE.001.055.A.525113.00001 | L22: 3500000 | O22: 411121 | P22: 25000 | S22: KU.201/1200/APTP/2026 | T22: 46064 | U22: =IF(ISBLANK(K22),"",IF(MID(K22,23,2)="52","Belanja Barang","Belanja Modal")) -> Belanja Barang | V22: GUNAWAN
A23: 22 | B23: 46066 | C23: SPM-BLU/APTP-2026/0022 | D23: NON REMUNERASI | E23: SP2D BLU - TRF | F23: CV. RAZALINE BERSAUDARA | G23: Pembayaran Belanja Barang Pemeliharaan Instalasi Air Bekas di Gedung Terminal | K23: =Pagu_BLU!I39 -> GA.4647.CDE.001.054.B.525114.00003 | L23: 49978305 | M23: 411211 | N23: 4952805 | O23: 411124 | P23: 900510 | S23: PL.108/0096/PPK.BB/APTP/2026 | T23: 46064 | U23: =IF(ISBLANK(K23),"",IF(MID(K23,23,2)="52","Belanja Barang","Belanja Modal")) -> Belanja Barang | V23: GUNAWAN
A24: 23 | B24: 46066 | C24: SPM-BLU/APTP-2026/0023 | D24: NON REMUNERASI | E24: SP2D BLU - TRF | F24: PT. ANGKASA JAYA SERVIS | G24: Pembayaran Belanja Barang Pengadaan Suku Cadang Listrik Tahap III | K24: =Pagu_BLU!I33 -> GA.4647.CDE.001.054.A.525112.00002 | L24: 49617000 | M24: 411211 | N24: 4917000 | O24: 411122 | P24: 670500 | S24: PL.108/0099/PPK.BB/APTP/2026 | T24: 46066 | U24: =IF(ISBLANK(K24),"",IF(MID(K24,23,2)="52","Belanja Barang","Belanja Modal")) -> Belanja Barang | V24: GUNAWAN
A25: 24 | B25: 46066 | C25: SPM-BLU/APTP-2026/0024 | D25: NON REMUNERASI | E25: SP2D BLU - TRF | F25: PT. ANGKASA JAYA SERVIS | G25: Pembayaran Belanja Barang Pengadaan Suku Cadang Listrik Tahap IV | K25: =Pagu_BLU!I33 -> GA.4647.CDE.001.054.A.525112.00002 | L25: 45887400 | M25: 411211 | N25: 4547000 | O25: 411122 | P25: 620100 | S25: PL.108/0102/PPK.BB/APTP/2026 | T25: 46066 | U25: =IF(ISBLANK(K25),"",IF(MID(K25,23,2)="52","Belanja Barang","Belanja Modal")) -> Belanja Barang | V25: GUNAWAN
A26: 25 | B26: 46066 | C26: SPM-BLU/APTP-2026/0025 | D26: NON REMUNERASI | E26: SP2D BLU - TRF | F26: PT. ANGKASA JAYA SERVIS | G26: Pembayaran Belanja Barang Kegiatan Kerohanian | K26: =Pagu_BLU!I106 -> WA.4613.EBA.960.053.A.525112.00003 | L26: 15540000 | M26: 411211 | N26: 1540000 | O26: 411124 | P26: 280000 | S26: PL.108/0105/PPK.BB/APTP/2026 | T26: 46066 | U26: =IF(ISBLANK(K26),"",IF(MID(K26,23,2)="52","Belanja Barang","Belanja Modal")) -> Belanja Barang | V26: GUNAWAN
A27: 26 | B27: 46073 | C27: SPM-BLU/APTP-2026/0026 | D27: NON REMUNERASI | E27: SP2D BLU - TRF | F27: PT. JAYA KENCANA | G27: Pembayaran Belanja Barang (Perawatan berkala) Preventive Maintenance Elevator dan Escalator Periode Januari 2026 | K27: =Pagu_BLU!I41 -> GA.4647.CDE.001.054.B.525114.00005 | L27: 10500600 | M27: 411211 | N27: 1040600 | O27: 411128 | P27: 250690 | S27: PL.108/0108/PPK.BB/APTP/2026 | T27: 46066 | U27: =IF(ISBLANK(K27),"",IF(MID(K27,23,2)="52","Belanja Barang","Belanja Modal")) -> Belanja Barang | V27: GUNAWAN
A28: 27 | B28: 46073 | C28: SPM-BLU/APTP-2026/0027 | D28: NON REMUNERASI | E28: SP2D BLU - TRF | F28: PT. JAYA KENCANA | G28: Pembayaran Belanja Pengadaan Suku Cadang Peralatan Mekanikal | K28: =Pagu_BLU!I35 -> GA.4647.CDE.001.054.A.525112.00004 | L28: 39793500 | M28: 411211 | N28: 3943500 | O28: 411122 | P28: 537750 | S28: PL.108/0115/PPK.BB/APTP/2026 | T28: 46071 | U28: =IF(ISBLANK(K28),"",IF(MID(K28,23,2)="52","Belanja Barang","Belanja Modal")) -> Belanja Barang | V28: GUNAWAN
A29: 28 | B29: 46073 | C29: SPM-BLU/APTP-2026/0028 | D29: NON REMUNERASI | E29: SP2D BLU - TRF | F29: PT. ANGKASA JAYA SERVIS | G29: Pembayaran Belanja Barang Kegiatan Kerohanian | K29: =Pagu_BLU!I106 -> WA.4613.EBA.960.053.A.525112.00003 | L29: 13986000 | M29: 411211 | N29: 1386000 | O29: 411124 | P29: 252000 | S29: PL.108/0126/PPK.BB/APTP/2026 | T29: 46072 | U29: =IF(ISBLANK(K29),"",IF(MID(K29,23,2)="52","Belanja Barang","Belanja Modal")) -> Belanja Barang | V29: GUNAWAN
A30: 29 | B30: 46073 | C30: SPM-BLU/APTP-2026/0029 | D30: NON REMUNERASI | E30: SP2D BLU - TRF | F30: PARA PEGAWAI KANTOR UPBU AJI PANGERAN TUMENGGUNG PRANOTO | G30: Belanja Barang Perjalanan Dinas Pegawai - Tiket | K30: =Pagu_BLU!I82 -> WA.4611.EBD.001.056.B.525115.00004 | L30: 16791441 | S30: KU.201/0928/APTP/2026 | T30: 46057 | U30: =IF(ISBLANK(K30),"",IF(MID(K30,23,2)="52","Belanja Barang","Belanja Modal")) -> Belanja Barang | V30: GUNAWAN
A31: 30 | B31: 46073 | C31: SPM-BLU/APTP-2026/0030 | D31: NON REMUNERASI | E31: SP2D BLU - TRF | F31: PARA PEGAWAI KANTOR UPBU AJI PANGERAN TUMENGGUNG PRANOTO | G31: Belanja Barang Perjalanan Dinas Pegawai - Hotel | K31: =Pagu_BLU!I81 -> WA.4611.EBD.001.056.B.525115.00003 | L31: 14090000 | S31: KU.201/0928/APTP/2026 | T31: 46057 | U31: =IF(ISBLANK(K31),"",IF(MID(K31,23,2)="52","Belanja Barang","Belanja Modal")) -> Belanja Barang | V31: GUNAWAN
A32: 31 | B32: 46073 | C32: SPM-BLU/APTP-2026/0031 | D32: NON REMUNERASI | E32: SP2D BLU - TRF | F32: PARA PEGAWAI KANTOR UPBU AJI PANGERAN TUMENGGUNG PRANOTO | G32: Belanja Barang Perjalanan Dinas Pegawai - Uang Harian | K32: =Pagu_BLU!I79 -> WA.4611.EBD.001.056.B.525115.00001 | L32: 11250000 | S32: KU.201/0928/APTP/2026 | T32: 46057 | U32: =IF(ISBLANK(K32),"",IF(MID(K32,23,2)="52","Belanja Barang","Belanja Modal")) -> Belanja Barang | V32: GUNAWAN
A33: 32 | B33: 46073 | C33: SPM-BLU/APTP-2026/0032 | D33: NON REMUNERASI | E33: SP2D BLU - TRF | F33: PARA PEGAWAI KANTOR UPBU AJI PANGERAN TUMENGGUNG PRANOTO | G33: Belanja Barang Perjalanan Dinas Pegawai - Tiket | K33: =Pagu_BLU!I82 -> WA.4611.EBD.001.056.B.525115.00004 | L33: 22789345 | S33: KU.201/1245/APTP/2026 | T33: 46071 | U33: =IF(ISBLANK(K33),"",IF(MID(K33,23,2)="52","Belanja Barang","Belanja Modal")) -> Belanja Barang | V33: GUNAWAN
A34: 33 | B34: 46073 | C34: SPM-BLU/APTP-2026/0033 | D34: NON REMUNERASI | E34: SP2D BLU - TRF | F34: PARA PEGAWAI KANTOR UPBU AJI PANGERAN TUMENGGUNG PRANOTO | G34: Belanja Barang Perjalanan Dinas Pegawai - Taxi | K34: =Pagu_BLU!I80 -> WA.4611.EBD.001.056.B.525115.00002 | L34: 1645160 | S34: KU.201/1245/APTP/2026 | T34: 46071 | U34: =IF(ISBLANK(K34),"",IF(MID(K34,23,2)="52","Belanja Barang","Belanja Modal")) -> Belanja Barang | V34: GUNAWAN
A35: 34 | B35: 46073 | C35: SPM-BLU/APTP-2026/0034 | D35: NON REMUNERASI | E35: SP2D BLU - TRF | F35: PARA PEGAWAI KANTOR UPBU AJI PANGERAN TUMENGGUNG PRANOTO | G35: Belanja Barang Perjalanan Dinas Pegawai - Hotel | K35: =Pagu_BLU!I81 -> WA.4611.EBD.001.056.B.525115.00003 | L35: 16270000 | S35: KU.201/1245/APTP/2026 | T35: 46071 | U35: =IF(ISBLANK(K35),"",IF(MID(K35,23,2)="52","Belanja Barang","Belanja Modal")) -> Belanja Barang | V35: GUNAWAN
A36: 35 | B36: 46073 | C36: SPM-BLU/APTP-2026/0035 | D36: NON REMUNERASI | E36: SP2D BLU - TRF | F36: PARA PEGAWAI KANTOR UPBU AJI PANGERAN TUMENGGUNG PRANOTO | G36: Belanja Barang Perjalanan Dinas Pegawai - Uang Harian | K36: =Pagu_BLU!I79 -> WA.4611.EBD.001.056.B.525115.00001 | L36: 12100000 | S36: KU.201/1245/APTP/2026 | T36: 46071 | U36: =IF(ISBLANK(K36),"",IF(MID(K36,23,2)="52","Belanja Barang","Belanja Modal")) -> Belanja Barang | V36: GUNAWAN
A37: 36 | B37: 46073 | C37: SPM-BLU/APTP-2026/0036 | D37: NON REMUNERASI | E37: SP2D BLU - TRF | F37: PARA PEGAWAI KANTOR UPBU AJI PANGERAN TUMENGGUNG PRANOTO | G37: Belanja Barang Perjalanan Dinas Pegawai - Tiket | K37: =Pagu_BLU!I82 -> WA.4611.EBD.001.056.B.525115.00004 | L37: 15439000 | S37: KU.201/1246/APTP/2026 | T37: 46071 | U37: =IF(ISBLANK(K37),"",IF(MID(K37,23,2)="52","Belanja Barang","Belanja Modal")) -> Belanja Barang | V37: GUNAWAN
A38: 37 | B38: 46073 | C38: SPM-BLU/APTP-2026/0037 | D38: NON REMUNERASI | E38: SP2D BLU - TRF | F38: PARA PEGAWAI KANTOR UPBU AJI PANGERAN TUMENGGUNG PRANOTO | G38: Belanja Barang Perjalanan Dinas Pegawai - Taxi | K38: =Pagu_BLU!I80 -> WA.4611.EBD.001.056.B.525115.00002 | L38: 1901010 | S38: KU.201/1246/APTP/2026 | T38: 46071 | U38: =IF(ISBLANK(K38),"",IF(MID(K38,23,2)="52","Belanja Barang","Belanja Modal")) -> Belanja Barang | V38: GUNAWAN
A39: 38 | B39: 46073 | C39: SPM-BLU/APTP-2026/0038 | D39: NON REMUNERASI | E39: SP2D BLU - TRF | F39: PARA PEGAWAI KANTOR UPBU AJI PANGERAN TUMENGGUNG PRANOTO | G39: Belanja Barang Perjalanan Dinas Pegawai - Hotel | K39: =Pagu_BLU!I81 -> WA.4611.EBD.001.056.B.525115.00003 | L39: 5900000 | S39: KU.201/1246/APTP/2026 | T39: 46071 | U39: =IF(ISBLANK(K39),"",IF(MID(K39,23,2)="52","Belanja Barang","Belanja Modal")) -> Belanja Barang | V39: GUNAWAN
A40: 39 | B40: 46073 | C40: SPM-BLU/APTP-2026/0039 | D40: NON REMUNERASI | E40: SP2D BLU - TRF | F40: PARA PEGAWAI KANTOR UPBU AJI PANGERAN TUMENGGUNG PRANOTO | G40: Belanja Barang Perjalanan Dinas Pegawai - Uang Harian | K40: =Pagu_BLU!I79 -> WA.4611.EBD.001.056.B.525115.00001 | L40: 5290000 | S40: KU.201/1246/APTP/2026 | T40: 46071 | U40: =IF(ISBLANK(K40),"",IF(MID(K40,23,2)="52","Belanja Barang","Belanja Modal")) -> Belanja Barang | V40: GUNAWAN
...

Sheet ViewSPMi_BLU
A1: KEMENTERIAN PERHUBUNGAN | Q1: 16
A2: BADAN LAYANAN UMUM
A3: KANTOR UNIT PENYELENGGARA BANDAR UDARA AJI PANGERAN TUMENGGUNG PRANOTO
A4: SURAT PERINTAH MEMBAYAR BLU
A5: Nomor : | B5: =INDEX(DataPembayaran_BLU!$C$2:$C$700,MATCH(ViewSPMi_BLU!$Q$1,DataPembayaran_BLU!$A$2:$A$700,0)) -> SPM-BLU/APTP-2026/0016 | J5: Tanggal : | K5: =INDEX(DataPembayaran_BLU!$B$2:$B$700,MATCH(ViewSPMi_BLU!$Q$1,DataPembayaran_BLU!$A$2:$A$700,0)) -> 46057 | O5: Hal. 1 dari 1
A6: Bendahara Pengeluaran, Badan Layanan Umum Kantor UPBU Aji Pangeran Tumenggung Pranoto
A7: Agar melakukan pembayaran tagihan sejumlah | J7: =M21 -> 46762080
A8: ="**** "&UPPER(terbilang(J7))&" "&"RUPIAH"&" ****" -> #NAME?
A9: Tahun Anggaran : 2026 | I9: No. Kontrak | K9: =IF(INDEX(data_pembayaran_no_kontrak,MATCH(ViewSPMi_BLU!$Q$1,data_pembayaran_no_transaksi,0))=0,"",INDEX(data_pembayaran_no_kontrak,MATCH(ViewSPMi_BLU!$Q$1,data_pembayaran_no_transaksi,0))) | M9: Jenis Tagihan | O9: =": "&INDEX(DataPembayaran_BLU!$D$2:$D$500,MATCH(ViewSPMi_BLU!$Q$1,DataPembayaran_BLU!$A$2:$A$500,0)) -> : NON REMUNERASI
A10: Dasar Pembayaran | M10: Jatuh Tempo | O10: : Segera
A11: DIPA | I11: Tgl. Kontrak | K11: =IF(INDEX(data_pembayaran_tanggal_kontrak,MATCH(ViewSPMi_BLU!$Q$1,data_pembayaran_no_transaksi,0))=0,"",INDEX(data_pembayaran_tanggal_kontrak,MATCH(ViewSPMi_BLU!$Q$1,data_pembayaran_no_transaksi,0))) | M11: Cara Bayar | O11: =": "&INDEX(DataPembayaran_BLU!$E$2:$E$700,MATCH(ViewSPMi_BLU!$Q$1,DataPembayaran_BLU!$A$2:$A$700,0)) -> : SP2D BLU - TRF
A12: Nomor : DIPA-022.05.2.288745/2026 | I12: No. BAST | K12: =IF(INDEX(DataPembayaran_BLU!$S$2:$S$700,MATCH(ViewSPMi_BLU!$Q$1,DataPembayaran_BLU!$A$2:$A$700,0))=0,"",INDEX(DataPembayaran_BLU!$S$2:$S$700,MATCH(ViewSPMi_BLU!$Q$1,DataPembayaran_BLU!$A$2:$A$700,0))) -> PL.108/0086/PPK.BB/APTP/2026
A13: Tanggal : 01 Desember 2025
A14: UU NOMOR 17 TAHUN 2025 TENTANG APBN TAHUN ANGGARAN 2026 | I14: Tgl. BAST | K14: =IF(INDEX(DataPembayaran_BLU!$T$2:$T$700,MATCH(ViewSPMi_BLU!$Q$1,DataPembayaran_BLU!$A$2:$A$700,0))=0,"",INDEX(DataPembayaran_BLU!$T$2:$T$700,MATCH(ViewSPMi_BLU!$Q$1,DataPembayaran_BLU!$A$2:$A$700,0))) -> 46056
A16: PENGELUARAN | M16: JUMLAH UANG
A17: =INDEX(DataPembayaran_BLU!$K$2:$K$700,MATCH(ViewSPMi_BLU!$Q$1,DataPembayaran_BLU!$A$2:$A$700,0)) -> GA.4647.CDE.001.054.A.525112.00001 | M17: =INDEX(DataPembayaran_BLU!$L$2:$L$700,MATCH(ViewSPMi_BLU!$Q$1,DataPembayaran_BLU!$A$2:$A$700,0)) -> 46762080
A21: Jumlah Pengeluaran | M21: =SUM(M17:O19) -> 46762080
A22: POTONGAN | M22: JUMLAH UANG
A23: =IF(INDEX(DataPembayaran_BLU!$M$2:$M$700,MATCH(ViewSPMi_BLU!$Q$1,DataPembayaran_BLU!$A$2:$A$700,0))=0,"",INDEX(DataPembayaran_BLU!$M$2:$M$700,MATCH(ViewSPMi_BLU!$Q$1,DataPembayaran_BLU!$A$2:$A$700,0))) -> 411211 | M23: =IF(INDEX(DataPembayaran_BLU!$N$2:$N$700,MATCH(ViewSPMi_BLU!$Q$1,DataPembayaran_BLU!$A$2:$A$700,0))=0,"",INDEX(DataPembayaran_BLU!$N$2:$N$700,MATCH(ViewSPMi_BLU!$Q$1,DataPembayaran_BLU!$A$2:$A$700,0))) -> 4634080
A24: =IF(INDEX(DataPembayaran_BLU!$O$2:$O$700,MATCH(ViewSPMi_BLU!$Q$1,DataPembayaran_BLU!$A$2:$A$700,0))=0,"",INDEX(DataPembayaran_BLU!$O$2:$O$700,MATCH(ViewSPMi_BLU!$Q$1,DataPembayaran_BLU!$A$2:$A$700,0))) -> 411122 | M24: =IF(INDEX(DataPembayaran_BLU!$P$2:$P$700,MATCH(ViewSPMi_BLU!$Q$1,DataPembayaran_BLU!$A$2:$A$700,0))=0,"",INDEX(DataPembayaran_BLU!$P$2:$P$700,MATCH(ViewSPMi_BLU!$Q$1,DataPembayaran_BLU!$A$2:$A$700,0))) -> 631920
A27: Jumlah Potongan | M27: =SUM(M23:O25) -> 5266000
A28: TOTAL PEMBAYARAN | M28: =M21-M27 -> 41496080
A30: Nama Supplier | E30: : | F30: =INDEX(DataPembayaran_BLU!$F$2:$F$700,MATCH(ViewSPMi_BLU!$Q$1,DataPembayaran_BLU!$A$2:$A$700,0)) -> PT. ANGKASA JAYA SERVIS | L30: Bank/Pos | M30: =": "&INDEX(supplier_bank,MATCH($F$30,supplier,0)) -> : Bank Tabungan Negara
L31: Rekening | M31: =": "&INDEX(supplier_rekening,MATCH($F$30,supplier,0)) -> : 2001880001341
A32: NPWP | E32: : | F32: =INDEX(supplier_npwp,MATCH($F$30,supplier,0)) -> 0539247528722000 | L32: Nama | M32: =": "&INDEX(supplier_nama_rekening,MATCH($F$30,supplier,0)) -> : PT. ANGKASA JAYA SERVIS
A33: Alamat | E33: : | F33: =INDEX(supplier_alamat,MATCH($F$30,supplier,0)) -> Jl. Poros Samarinda - Bontang, Kel. Sungai Siring, Samarinda-Kalimantan Timur | L33: Uraian | M33: =": "&IFERROR(INDEX(DataPembayaran_BLU!$G$2:$G$700,MATCH(ViewSPMi_BLU!$Q$1,DataPembayaran_BLU!$A$2:$A$700,0)),"") -> : Pembayaran Belanja Barang Suku Cadang Peralatan Elektronika
A43: Semua bukti-bukti pengeluaran yang disahkan Pejabat Pembuat Komitmen telah | M43: Samarinda, | N43: =INDEX(DataPembayaran_BLU!$B$2:$B$700,MATCH(ViewSPMi_BLU!$Q$1,DataPembayaran_BLU!$A$2:$A$700,0)) -> 46057
A44: diuji dan dinyatakan memenuhi persyaratan untuk dilakukan pembayaran atas | M44: A.n. Kuasa Pengguna Anggaran
A45: beban BLU, selanjutnya bukti-bukti pengeluaran dimaksud disimpan dan | M45: Pejabat Penandatangan SPM
A46: ditatausahakan oleh Pejabat Penandatangan SPM
A47: Kebenaran perhitungan dan isi yang tertuang dalam SPM ini menjadi tanggung
A48: jawab Pejabat Penandatangan SPM.
M50: =INDEX(nama_pejabat,MATCH($M$45,DataPejabat!$D$2:$D$9,0)) -> MUTIA RACHMI
M51: ="NIP "&IFERROR(INDEX(nip_pejabat,MATCH($M$50,nama_pejabat,0)),"") -> NIP 198201112002122002

Sheet ViewSPPi_BLU
A1: KEMENTERIAN PERHUBUNGAN | Q1: 25
A2: BADAN LAYANAN UMUM
A3: KANTOR UNIT PENYELENGGARA BANDAR UDARA AJI PANGERAN TUMENGGUNG PRANOTO
A4: SURAT PERMINTAAN PEMBAYARAN BLU
