Workbook
Name _1960.011.011.521219: WASJA!$D$13
Name Daftar_Rekanan: Referensi!#REF!
Name Daftar_Rekanan: SETUP!$V$6:$Y$10
Name JAKARTA: [1]SETUP!$V$6:$Y$10
Name Jenis_Pembayaran: Referensi!#REF!
Name Jenis_Pembayaran: Referensi!$O$16:$O$21
Name Keg_Output_Akun: SETUP!$N$12:$N$66
Name Keg_Output_Komp_Akun: Referensi!$L$6:$L$34
Name Keg_Output_Komp_Akun: SETUP!$L$12:$S$66
Name Klabel: Referensi!#REF!
Name Klabel: Referensi!$K$6:$K$15
Name Kode: Referensi!#REF!
Name Kode: Referensi!$G$6:$G$39
Name Nama_Buku: SETUP!$H$7:$I$18
Name Output_01: SETUP!$N$12:$N$66
Name Output_02: Referensi!$N$31
Name Output_03: Referensi!$N$32:$N$33
Name Output_04: Referensi!$N$34:$N$39
Name Output_06: Referensi!$N$40
Name Rekanan: Referensi!#REF!
Name Rekanan: SETUP!$V$6:$V$10
Name Sifat_Pembayaran: Referensi!#REF!
Name Sifat_Pembayaran: Referensi!$O$6:$O$11

Sheet MENU
C6: Klik Pilihan Anda | G6: Klik Pilihan Anda
C8: SETUP USER | I8: BP-UANG PERSEDIAAN
C10: REFERENSI | G10: BUKU KAS UMUM | I10: BP-LS BENDAHARA
C12: INPUT DATA TRANSAKSI | G12: BUKU PEMBANTU KAS | I12: BP-PAJAK
C14: SURAT PERMINTAAN PEMBAYARAN | G14: BUKU PEMBANTU BANK | I14: BUKU LAIN-LAIN
C16: S P T B | G16: BUKU PEMBANTU BPP | I16: BERITA ACARA PEMERIKSAAN KAS
C18: Sistem Pembukuan Bendahara | G18: BP-UANG MUKA PERJADIN | I18: LAPORAN PERTANGGUNGJAWABAN

Sheet SETUP
C1: Back to Menu
C3: SETUP USER | H3: SALDO AWAL BUKU | J3: 46023 | L3: PAGU DIPA & SALDO AWAL BULAN BERJALAN | U3: PIHAK YANG BERHAK MENERIMA
C5: ITEM | E5: URAIAN | F5: KODE | H5: KODE | I5: NAMA BUKU | J5: SALDO AWAL | L5: Kode | M5: Akun | N5: Keg/O/Akun | O5: PAGU DIPA | P5: SALDO AWAL | Q5: Akun | R5: Klabel | S5: Uraian Klasifikasi Belanja | U5: Kode | V5: Nama | W5: Alamat | X5: Bank | Y5: Norek
C6: KN/Lembaga | D6: : | E6: Perhubungan | F6: 022 | L6: 04.08 | N6: Lembaga Eksekutif & Legislatif, Keuangan & Fiskal, serta Urusan Luar Negeri | U6: 001 | V6: Bendahara Pengeluaran Balai Diklat Contoh Bandung | W6: Jl. Asia Afrika 100 Bandung | X6: Bank Jabar Bandung | Y6: 00.12345
C7: Unit Organisasi | D7: : | E7: Dirjen Perhubungan Udara | F7: 05 | H7: 1 | I7: BUKU KAS UMUM | J7: 66573.83 | L7: 022.05.09 | N7: Program Pendidikan dan Pelatihan Aparatur Kementerian Keuangan | U7: 002 | V7: CV Rahayu | W7: Jl. Pelanduk 12 Bandung | X7: Bank Mandiri Bandung | Y7: 123456789
C8: SatKer/SKS | D8: : | E8: BLU Kantor UPBU A.P.T. Pranoto Samarinda | F8: 288745 | H8: 2 | I8: BUKU PEMBANTU KAS TUNAI | J8: 0 | L8: 1960 | N8: Pelayanan Angkutan Udara Perintis | U8: 003
C9: Lokasi | D9: : | E9: Kalimantan Timur | F9: 1300 | H9: 3 | I9: BUKU PEMBANTU BANK | J9: 66573.83 | L9: 1961 | N9: Pembangunan, Rehabilitasi dan Pemeliharaan Prasarana Bandar Udara | U9: 004
C10: Tempat | D10: : | E10: Samarinda | F10: 1306 | H10: 4 | I10: BUKU PEMBANTU BPP | J10: 0 | L10: 1962 | N10: Pembangunan, Rehabilitasi dan Pemeliharaan Prasarana Keamanan Penerbangan | U10: 005
C11: Alamat | D11: : | E11: Jalan Poros Samarinda - Bontang | H11: 5 | I11: BUKU PEMBANTU UANG PERSEDIAAN | J11: 0 | L11: 1965 | N11: Dukungan Manajemen dan Dukungan Teknis Lainnya Ditjen Perhubungan Udara | U11: 006
C12: Fungsi/SubFungsi | D12: : | E12: Ekonomi, Transportasi | F12: 04.08 | H12: 6 | I12: BUKU PEMBANTU LS BENDAHARA | J12: 0 | L12: 1965.994.001. | M12: 511111 | N12: =L12&M12 -> 1965.994.001.511111 | O12: 1938305000 | P12: 1938305000 | Q12: =M12 -> 511111 | R12: =LEFT(Q12,4) -> 5111 | U12: 007
C13: Kegiatan | D13: : | H13: 7 | I13: BUKU PEMBANTU UANG MUKA PERJADIN | J13: 0 | L13: 1965.994.001. | M13: 511119 | N13: =L13&M13 -> 1965.994.001.511119 | O13: 38000 | P13: 38000 | Q13: =M13 -> 511119 | R13: =LEFT(Q13,4) -> 5111 | U13: 008
C14: Kewenangan | D14: : | E14: KD | H14: 8 | I14: BUKU PEMBANTU PAJAK UP | J14: 0 | L14: 1965.994.001. | M14: 511121 | N14: =L14&M14 -> 1965.994.001.511121 | O14: 141730000 | P14: 141730000 | Q14: =M14 -> 511121 | R14: =LEFT(Q14,4) -> 5111 | U14: 009
C15: Tanggal DIPA | D15: : | E15: 05 Desember 2013 | H15: 9 | I15: BUKU PEMBANTU BUNGA REKENING | J15: 66573.83 | L15: 1965.994.001. | M15: 511122 | N15: =L15&M15 -> 1965.994.001.511122 | O15: 41396000 | P15: 41396000 | Q15: =M15 -> 511122 | R15: =LEFT(Q15,4) -> 5111 | U15: 010
C16: Nomor DIPA | D16: : | E16: SP DIPA-022.05.2.413922/2014 | H16: 10 | I16: BUKU PEMBANTU PAJAK UP & LS | J16: 0 | L16: 1965.994.001. | M16: 511123 | N16: =L16&M16 -> 1965.994.001.511123 | O16: 16380000 | P16: 16380000 | Q16: =M16 -> 511123 | R16: =LEFT(Q16,4) -> 5111
C17: Tahun Anggaran | D17: : | E17: 2024 | H17: 11 | I17: BUKU PENGESAHAN BELANJA | J17: - | L17: 1965.994.001. | M17: 511124 | N17: =L17&M17 -> 1965.994.001.511124 | O17: 94900000 | P17: 94900000 | Q17: =M17 -> 511124 | R17: =LEFT(Q17,4) -> 5111
C18: KPPN Pembayar | D18: : | E18: Samarinda | F18: 094 | H18: 12 | I18: BUKU PENGEMBALIAN BELANJA | L18: 1965.994.001. | M18: 511125 | N18: =L18&M18 -> 1965.994.001.511125 | O18: 67594000 | P18: 67594000 | Q18: =M18 -> 511125 | R18: =LEFT(Q18,4) -> 5111
C19: Nama KPA | D19: : | E19: MAEKA RINDRA HARIYANTO, SE.,M.SI | L19: 1965.994.001. | M19: 511126 | N19: =L19&M19 -> 1965.994.001.511126 | O19: 150699000 | P19: 150699000 | Q19: =M19 -> 511126 | R19: =LEFT(Q19,4) -> 5111
C20: NIP KPA | D20: : | E20: 197705111997031002 | H20: SALDO AKHIR BUKU | J20: =MAX(Input_Transaksi!C11:C556) -> 46051 | L20: 1965.994.001. | M20: 511129 | N20: =L20&M20 -> 1965.994.001.511129 | O20: 409200000 | P20: 409200000 | Q20: =M20 -> 511129 | R20: =LEFT(Q20,4) -> 5111
C21: Nama Penguji SPP | D21: : | L21: 1965.994.001. | M21: 511151 | N21: =L21&M21 -> 1965.994.001.511151 | O21: 103643000 | P21: 103643000 | Q21: =M21 -> 511151 | R21: =LEFT(Q21,4) -> 5111
C22: NIP Penguji SPP | D22: : | H22: KODE | I22: NAMA BUKU | J22: SALDO AWAL | L22: 1960.011.011. | M22: 521219 | N22: =L22&"."&M22 -> 1960.011.011..521219 | O22: 10667571000 | P22: 10667571000 | Q22: =M22 -> 521219 | R22: =LEFT(Q22,4) -> 5212
C23: Nama Bendahara Pengeluaran | D23: : | L23: 1960.011.011. | M23: 521219 | N23: =L23&"."&M23 -> 1960.011.011..521219 | O23: 2200000000 | P23: 2200000000 | Q23: =M23 -> 521219 | R23: =LEFT(Q23,4) -> 5212
C24: NIP Bendahara Pengeluaran | D24: : | H24: 1 | I24: BUKU KAS UMUM | J24: =BKU!H300 -> 0 | L24: 1961.003.011. | M24: 522131 | N24: =L24&"."&M24 -> 1961.003.011..522131 | O24: 1550000000 | P24: 1550000000 | Q24: =M24 -> 522131 | R24: =LEFT(Q24,4) -> 5221
H25: 2 | I25: BUKU PEMBANTU KAS TUNAI | J25: =TUNAI!H558 -> 0 | L25: 1961.014.011. | M25: 521213 | N25: =L25&"."&M25 -> 1961.014.011..521213 | O25: 37500000 | P25: 37500000 | Q25: =M25 -> 521213 | R25: =LEFT(Q25,4) -> 5212
H26: 3 | I26: BUKU PEMBANTU BANK | J26: =BANK!H300 -> 0 | L26: 1961.014.011. | M26: 521219 | N26: =L26&"."&M26 -> 1961.014.011..521219 | O26: 40000000 | P26: 40000000 | Q26: =M26 -> 521219 | R26: =LEFT(Q26,4) -> 5212
H27: 4 | I27: BUKU PEMBANTU BPP | J27: 0 | L27: 1965.003.015. | M27: 521115 | N27: =L27&"."&M27 -> 1965.003.015..521115 | O27: 56400000 | P27: 56400000 | Q27: =M27 -> 521115 | R27: =LEFT(Q27,4) -> 5211
H28: 5 | I28: BUKU PEMBANTU UANG PERSEDIAAN | J28: 0 | L28: 1965.003.040. | M28: 521115 | N28: =L28&"."&M28 -> 1965.003.040..521115 | O28: 51840000 | P28: 51840000 | Q28: =M28 -> 521115 | R28: =LEFT(Q28,4) -> 5211
H29: 6 | I29: BUKU PEMBANTU LS BENDAHARA | J29: =LSB!H300 -> 0 | L29: 1965.003.040. | M29: 521119 | N29: =L29&"."&M29 -> 1965.003.040..521119 | O29: 160000000 | P29: 160000000 | Q29: =M29 -> 521119 | R29: =LEFT(Q29,4) -> 5211
H30: 7 | I30: BUKU PEMBANTU UANG MUKA PERJADIN | J30: =PERJADIN!H300 -> 0 | L30: 1965.003.012. | M30: 521211 | N30: =L30&"."&M30 -> 1965.003.012..521211 | O30: 28600000 | P30: 28600000 | Q30: =M30 -> 521211 | R30: =LEFT(Q30,4) -> 5212
H31: 8 | I31: BUKU PEMBANTU PAJAK UP | J31: 0 | L31: 1965.003.013. | M31: 521211 | N31: =L31&"."&M31 -> 1965.003.013..521211 | O31: 5000000 | P31: 5000000 | Q31: =M31 -> 521211 | R31: =LEFT(Q31,4) -> 5212
H32: 9 | I32: BUKU PEMBANTU BUNGA REKENING | J32: =BUNGA!H300 -> 0 | L32: 1965.003.040. | M32: 521213 | N32: =L32&"."&M32 -> 1965.003.040..521213 | O32: 655800000 | P32: 655800000 | Q32: =M32 -> 521213 | R32: =LEFT(Q32,4) -> 5212
H33: 10 | I33: BUKU PEMBANTU PAJAK UP & LS | J33: =PJK_LS!M558 -> 0 | L33: 1965.003.013. | M33: 524111 | N33: =L33&"."&M33 -> 1965.003.013..524111 | O33: 92664000 | P33: 92664000 | Q33: =M33 -> 524111 | R33: =LEFT(Q33,4) -> 5241
H34: 11 | I34: BUKU PENGESAHAN BELANJA | J34: 0 | L34: 1965.003.040. | M34: 524111 | N34: =L34&"."&M34 -> 1965.003.040..524111 | O34: 100185000 | P34: 100185000 | Q34: =M34 -> 524111 | R34: =LEFT(Q34,4) -> 5241
H35: 12 | I35: BUKU PENGEMBALIAN BELANJA | J35: 0 | L35: 1965.003.013. | M35: 524119 | N35: =L35&"."&M35 -> 1965.003.013..524119 | O35: 46980000 | P35: 46980000 | Q35: =M35 -> 524119 | R35: =LEFT(Q35,4) -> 5241
L36: 1965.007.016. | M36: 521119 | N36: =L36&"."&M36 -> 1965.007.016..521119 | O36: 15000000 | P36: 15000000 | Q36: =M36 -> 521119 | R36: =LEFT(Q36,4) -> 5211
L37: 1965.007.017. | M37: 521213 | N37: =L37&"."&M37 -> 1965.007.017..521213 | O37: 10800000 | P37: 10800000 | Q37: =M37 -> 521213 | R37: =LEFT(Q37,4) -> 5212
L38: 1965.007.015. | M38: 523121 | N38: =L38&"."&M38 -> 1965.007.015..523121 | O38: 71983000 | P38: 71983000 | Q38: =M38 -> 523121 | R38: =LEFT(Q38,4) -> 5231
L39: 1965.007.014. | M39: 523133 | N39: =L39&"."&M39 -> 1965.007.014..523133 | O39: 567375000 | P39: 567375000 | Q39: =M39 -> 523133 | R39: =LEFT(Q39,4) -> 5231
L40: 1965.007.017. | M40: 524119 | N40: =L40&"."&M40 -> 1965.007.017..524119 | O40: 2700000 | P40: 2700000 | Q40: =M40 -> 524119 | R40: =LEFT(Q40,4) -> 5241
L41: 1965.994.002. | M41: 521111 | N41: =L41&"."&M41 -> 1965.994.002..521111 | O41: 389928000 | P41: 389928000 | Q41: =M41 -> 521111 | R41: =LEFT(Q41,4) -> 5211
L42: 1965.994.002. | M42: 521114 | N42: =L42&"."&M42 -> 1965.994.002..521114 | O42: 6000000 | P42: 6000000 | Q42: =M42 -> 521114 | R42: =LEFT(Q42,4) -> 5211
...

Sheet Referensi
C1: Back to Menu
C3: KODE TRANSAKSI | K3: KELOMPOK AKUN | N3: SIFAT PEMBAYARAN
C5: KODE | D5: URAIAN TRANSAKSI | K5: Kel. Akun | L5: Uraian Kelompok Akun | N5: Kode | O5: Sifat Pembayaran
C6: A | D6: Membukukan Pagu DIPA | G6: =C6&" "&D6 -> A Membukukan Pagu DIPA | K6: 5111 | L6: Belanja Gaji dan Tunjangan PNS | N6: 1 | O6: Pengeluaran Anggaran
G7: =C7&" "&D7 | K7: 5112 | L7: Belanja Gaji dan Tunjangan TNI/Polri | N7: 2 | O7: Pengembalian Uang Mata Anggaran
C8: C1 | D8: Terima Transfer Uang dari Rekening Bendahara Penerimaan (Bank) | G8: =C8&" "&D8 -> C1 Terima Transfer Uang dari Rekening Bendahara Penerimaan (Bank) | K8: 5113 | L8: Belanja Gaji dan Tunjangan Pejabat Negara | N8: 3 | O8: Perhitungan Fihak Ketiga
G9: =C9&" "&D9 | K9: 5114 | L9: Belanja Gaji Dokter PTT | N9: 4 | O9: Pengeluaran Transito
G10: =C10&" "&D10 | K10: 5115 | L10: Belanja Gaji dan Tunjangan Pegawai Non PNS | N10: 5 | O10: Perhitungan Reksus
G11: =C11&" "&D11 | K11: 5121 | L11: Belanja Honorarium | N11: 6 | O11: Pembetulan Pembukuan
G12: =C12&" "&D12 | K12: 5122 | L12: Belanja Lembur
G13: =C13&" "&D13 | K13: 5123 | L13: Belanja Vakasi | N13: JENIS PEMBAYARAN
C14: G1 | D14: Perpindahan dari Bank ke Tunai (Tarik Tunai) | G14: =C14&" "&D14 -> G1 Perpindahan dari Bank ke Tunai (Tarik Tunai) | K14: 5124 | L14: Belanja Tunjangan Khusus & Belanja Pgw Transito
C15: G2 | D15: Perpindahan dari Tunai ke Bank (Setor Tunai ke Rekening Bendahara Pengeluaran) | G15: =C15&" "&D15 -> G2 Perpindahan dari Tunai ke Bank (Setor Tunai ke Rekening Bendahara Pengeluaran) | K15: 5131 | L15: Belanja Pensiun dan Uang Tunggu | N15: Kode | O15: Jenis Pembayaran
G16: =C16&" "&D16 | K16: 5132 | L16: Belanja Asuransi Kesehatan | N16: 1 | O16: Dana Uang Persediaan (UP)
G17: =C17&" "&D17 | K17: 5133 | L17: Belanja Tunjangan Kesehatan Veteran | N17: 2 | O17: Tambahan Uang Persediaan (TU)
C18: I1 | D18: Belanja dengan cara LS - Tunai | G18: =C18&" "&D18 -> I1 Belanja dengan cara LS - Tunai | K18: 5134 | L18: Belanja Cadangan Perubahan Sharing | N18: 3 | O18: Penggantian Uang Persediaan (GU)
C19: I2 | D19: Belanja dengan cara LS - Bank | G19: =C19&" "&D19 -> I2 Belanja dengan cara LS - Bank | K19: 5211 | L19: Belanja Barang Operasional | N19: 4 | O19: Pembayaran Langsung (LS)
G20: =C20&" "&D20 | K20: 5212 | L20: Belanja Barang Non Operasional | N20: 5 | O20: Nihil
G21: =C21&" "&D21 | K21: 5221 | L21: Belanja Jasa | N21: 6 | O21: Pengesahan
G22: =C22&" "&D22 | K22: 5231 | L22: Belanja Biaya Pemeliharaan
G23: =C23&" "&D23 | K23: 5241 | L23: Belanja Perjalanan Dalam Negeri
C24: K1 | D24: Pemberian Uang Muka Perjadin (Tunai) | G24: =C24&" "&D24 -> K1 Pemberian Uang Muka Perjadin (Tunai) | K24: 5242 | L24: Belanja Perjalanan Luar Negeri
C25: K2 | D25: Pemberian Uang Muka Perjadin (Bank) | G25: =C25&" "&D25 -> K2 Pemberian Uang Muka Perjadin (Bank) | K25: 5251 | L25: Belanja Barang BLU
C26: K3 | D26: Perhitungan rampung Perjadin | G26: =C26&" "&D26 -> K3 Perhitungan rampung Perjadin | K26: 5311 | L26: Belanja Modal Tanah
C27: K4 | D27: Terima Sisa UM Perjadin (tunai) | G27: =C27&" "&D27 -> K4 Terima Sisa UM Perjadin (tunai) | K27: 5321 | L27: Belanja Modal Peralatan dan Mesin
C28: L1 | D28: Terima uang lain-lain - Bunga Rekening | G28: =C28&" "&D28 -> L1 Terima uang lain-lain - Bunga Rekening | K28: 5331 | L28: Belanja Modal Gedung dan Bangunan
G29: =C29&" "&D29 | K29: 5341 | L29: Belanja Modal Jalan, Irigasi, & Jaringan
C30: L3 | D30: Transfer Uang Bunga Rekening ke Rekening Bendahara Penerimaan | G30: =C30&" "&D30 -> L3 Transfer Uang Bunga Rekening ke Rekening Bendahara Penerimaan | K30: 5351 | L30: Belanja Pemeliharaan yang Dikapitalisasi
C31: M1 | D31: Pungut Pajak oleh Bendahara - Tunai | G31: =C31&" "&D31 -> M1 Pungut Pajak oleh Bendahara - Tunai | K31: 5361 | L31: Belanja Modal Fisik Lainnya
C32: M2 | D32: Setor Pajak oleh bendahara - Tunai | G32: =C32&" "&D32 -> M2 Setor Pajak oleh bendahara - Tunai | K32: 5371 | L32: Belanja Modal BLU
C33: M3 | D33: Penyetoran Pajak oleh Bendahara Pengeluaran Melalui Bank untuk Pajak Yang Belum disahkan | G33: =C33&" "&D33 -> M3 Penyetoran Pajak oleh Bendahara Pengeluaran Melalui Bank untuk Pajak Yang Belum disahkan | K33: 8251 | L33: Uang Persediaan
C34: L4 | D34: Terima uang lain-lain - Pengembalian Belanja | G34: =C34&" "&D34 -> L4 Terima uang lain-lain - Pengembalian Belanja
C35: L5 | D35: Transfer Uang Pengembalian Belanja pada Buku Pengembalian Belanja ke Rekening Bendahara Penerimaan | G35: =C35&" "&D35 -> L5 Transfer Uang Pengembalian Belanja pada Buku Pengembalian Belanja ke Rekening Bendahara Penerimaan
C36: L6 | D36: Transfer Uang Pengembalian Belanja pada Buku LS Bendahara ke Rekening Bendahara Penerimaan | G36: =C36&" "&D36 -> L6 Transfer Uang Pengembalian Belanja pada Buku LS Bendahara ke Rekening Bendahara Penerimaan
C37: L7 | D37: Terima Uang Retur | G37: =C37&" "&D37 -> L7 Terima Uang Retur
G38: =C38&" "&D38
G39: =C39&" "&D39
C40: M8 | D40: Pencatatan Pungut Pajak oleh Bendahara Pengeluaran | G40: =C40&" "&D40 -> M8 Pencatatan Pungut Pajak oleh Bendahara Pengeluaran
C41: M9 | D41: Pencatatan Penyetoran Pajak oleh Bendahara Pengeluaran (Bank) Yang sudah disahkan | G41: =C41&" "&D41 -> M9 Pencatatan Penyetoran Pajak oleh Bendahara Pengeluaran (Bank) Yang sudah disahkan
C42: R1 | D42: Transaksi Koreksi Non Belanja - Buku Pembantu Bunga Bank (D) dan Buku Pembantu LS Bendahara (K) | G42: =C42&" "&D42 -> R1 Transaksi Koreksi Non Belanja - Buku Pembantu Bunga Bank (D) dan Buku Pembantu LS Bendahara (K)
...

Sheet Input_Transaksi
C1: Back to Menu
C3: =SETUP!E8 -> BLU Kantor UPBU A.P.T. Pranoto Samarinda
C4: INPUT DATA TRANSAKSI
C5: PERIODE : 01 JANUARI S.D 31 JANUARI 2026
C7: DAFTAR KODE TRANSAKSI | F7: H1 Belanja dengan UP/TUP (tunai)
C9: Tanggal | D9: No. Bkt | E9: Kode Tran-saksi | F9: Uraian Transaksi | G9: , | H9: Penerima | I9: Keg/Output/ Akun | J9: CP (UP/LS/ GU) | K9: Pungut/Setor Pajak | L9: Jumlah Kotor | M9: Unsur Pajak dalam Belanja | P9: (1) BUKU KAS UMUM | AB9: (10) BUKU KAS | AL9: (2) BUKU KAS TUNAI | AR9: (3) BUKU KAS DI BANK | AZ9: (4) BUKU BPP | BF9: (5) BUKU PEMBANTU UP | BL9: (6) BUKU LS BENDAHARA | BR9: (7) BUKU UM PERJADIN | BX9: (8) BUKU PEMBANTU PAJAK | CD9: (9) BUKU PEMBANTU BUNGA REKENING | CJ9: (10) BUKU PEMBANTU PAJAK LS | CP9: Data SPTB | CQ9: Data PPN | CR9: Data PPh | CS9: (11) BUKU PEMBANTU PENGESAHAN | CY9: (12) BUKU PENGEMBALIAN Belanja
T10: TERIMA | AA10: KELUAR | AF10: TERIMA | AK10: KELUAR | AN10: TERIMA | AQ10: KELUAR | AT10: TERIMA | AY10: KELUAR | BB10: TERIMA | BE10: KELUAR | BH10: TERIMA | BK10: KELUAR | BL10: TERIMA | BM10: TERIMA | BN10: TERIMA | BQ10: KELUAR | BS10: TERIMA | BT10: TERIMA | BU10: 7 | BW10: KELUAR | BY10: TERIMA | BZ10: TERIMA | CC10: KELUAR | CF10: TERIMA | CI10: KELUAR | CK10: TERIMA | CL10: TERIMA | CO10: KELUAR | CS10: TERIMA | CT10: TERIMA | CU10: TERIMA | CX10: KELUAR | DA10: TERIMA | DD10: KELUAR
A11: 001 | C11: 46024 | D11: ="2026."&A11 -> 2026.001 | E11: L3 | F11: Transfer Uang Bunga Rekening RPL 046 BLU APT PRANOTO UTK OPS PENGELUARAN ke Rekening Bendahara Peneriman RPL 046 BLU APT PRANOTO UTK OPS | L11: 66573.83 | O11: =IF(E11="A",L11,IF(E11="B",L11,IF(E11="C1",L11,IF(E11="D1",L11,IF(E11="E",L11,IF(E11="F",L11,IF(E11="G1",L11,IF(E11="G2",L11,IF(E11="R1",L11,IF(E11="L4",L11,IF(E11="R2",L11,IF(E11="l7",L11,0)))))))))))) -> 0 | P11: =IF(E11="J1",L11,IF(E11="J2",L11,IF(E11="J4",L11,IF(E11="K1",L11,IF(E11="K2",L11,IF(E11="K4",L11,IF(E11="L1",L11,IF(E11="M1",L11,IF(E11="M6",L11,IF(E11="M6",L11,0)))))))))) -> 0 | Q11: =IF(E11="M4",L11,0) -> 0 | R11: 1 | S11: =IF(R11="","",VLOOKUP(R11,Nama_Buku,2)) -> BUKU KAS UMUM | T11: =AVERAGE(O11+P11+Q11) -> 0 | U11: =IF(E11="A",L11,IF(E11="C2",L11,IF(E11="D2",L11,IF(E11="E",L11,IF(E11="F",L11,IF(E11="G1",L11,IF(E11="G2",L11,IF(E11="H1",L11,IF(E11="R1",L11,0))))))))) -> 0 | V11: =IF(E11="H2",L11,IF(E11="I1",L11,IF(E11="I2",L11,IF(E11="J1",L11,IF(E11="J2",L11,IF(E11="J3",L11,IF(E11="J4",L11,IF(E11="K1",L11,0)))))))) -> 0 | W11: =IF(E11="K2",L11,IF(E11="K3",L11,IF(E11="K4",L11,IF(E11="L2",L11,IF(E11="L3",L11,IF(E11="M2",L11,IF(E11="M3",L11,IF(E11="M7",L11,IF(E11="L5",L11,IF(E11="L6",L11,0)))))))))) -> 66573.83 | X11: =IF(E11="N1",L11,IF(E11="N2",L11,0)) -> 0 | Y11: =R11 -> 1 | Z11: =IF(Y11="","",VLOOKUP(Y11,Nama_Buku,2)) -> BUKU KAS UMUM | AA11: =AVERAGE(U11+V11+W11+X11) -> 66573.83 | AB11: 10 | AC11: =IF(AB11="","",VLOOKUP(AB11,Nama_Buku,2)) -> BUKU PEMBANTU PAJAK UP & LS | AD11: =IF(E11="B",L11,IF(E11="C1",L11,IF(E11="D1",L11,IF(E11="J1",-L11,IF(E11="J2",-L11,IF(E11="L1",L11,IF(E11="M1",L11,IF(E11="M4",L11,IF(E11="M8",L11,IF(E11="R2",L11,0)))))))))) -> 0 | AE11: =IF(E11="K1",-L11,IF(E11="K2",-L11,)) -> 0 | AF11: =AVERAGE(AD11+AE11) -> 0 | AG11: =IF(E11="C2",L11,IF(E11="D2",L11,IF(E11="H1",L11,IF(E11="H2",L11,IF(E11="I1",L11,IF(E11="I2",L11,IF(E11="J4",-L11,IF(E11="K4",-L11,0)))))))) -> 0 | AH11: =IF(E11="L2",L11,IF(E11="L3",L11,IF(E11="M2",L11,IF(E11="M3",L11,IF(E11="M5",L11,IF(E11="N1",L11,IF(E11="N2",L11,0))))))) -> 66573.83 | AI11: =AB11 -> 10 | AJ11: =IF(AI11="","",VLOOKUP(AI11,Nama_Buku,2)) -> BUKU PEMBANTU PAJAK UP & LS | AK11: =AVERAGE(AG11+AH11) -> 66573.83 | AL11: 2 | AM11: =IF(AL11="","",VLOOKUP(AL11,Nama_Buku,2)) -> BUKU PEMBANTU KAS TUNAI | AN11: =IF(E11="G1",L11,IF(E11="J4",L11,IF(E11="K4",L11,IF(E11="M1",L11,0)))) -> 0 | AO11: =AL11 -> 2 | AP11: =IF(AO11="","",VLOOKUP(AO11,Nama_Buku,2)) -> BUKU PEMBANTU KAS TUNAI | AQ11: =IF(E11="G2",L11,IF(E11="H1",L11,IF(E11="I1",L11,IF(E11="J1",L11,IF(E11="K1",L11,IF(E11="L2",L11,IF(E11="M2",L11,IF(E11="N1",L11,0)))))))) -> 0 | AR11: 3 | AS11: =IF(AR11="","",VLOOKUP(AR11,Nama_Buku,2)) -> BUKU PEMBANTU BANK | AT11: =IF(E11="B",L11,IF(E11="C1",L11,IF(E11="D1",L11,IF(E11="G2",L11,IF(E11="L1",L11,IF(E11="L4",L11,IF(E11="R2",L11,IF(E11="L7",L11,0)))))))) -> 0 | AU11: =IF(E11="C2",L11,IF(E11="D2",L11,IF(E11="G1",L11,IF(E11="H2",L11,IF(E11="I2",L11,IF(E11="J2",L11,IF(E11="K2",L11,IF(E11="L3",L11,IF(E11="L5",L11,IF(E11="L6",L11,0)))))))))) -> 66573.83 | AV11: =IF(E11="M3",L11,IF(E11="N2",L11,IF(E11="M9",L11,0))) -> 0 | AW11: =AR11 -> 3 | AX11: =IF(AW11="","",VLOOKUP(AW11,Nama_Buku,2)) -> BUKU PEMBANTU BANK | AY11: =AVERAGE(AU11+AV11) -> 66573.83 | AZ11: 4 | BA11: =IF(AZ11="","",VLOOKUP(AZ11,Nama_Buku,2)) -> BUKU PEMBANTU BPP | BB11: =IF(E11="J1",L11,IF(E11="J2",L11,IF(E11="M4",L11,0))) -> 0 | BC11: =AZ11 -> 4 | BD11: =IF(BC11="","",VLOOKUP(BC11,Nama_Buku,2)) -> BUKU PEMBANTU BPP | BE11: =IF(E11="J3",L11,IF(E11="J4",L11,IF(E11="M5",L11,0))) -> 0 | BF11: 5 | BG11: =IF(BF11="","",VLOOKUP(BF11,Nama_Buku,2)) -> BUKU PEMBANTU UANG PERSEDIAAN | BH11: =IF(E11="B",L11,IF(E11="D1",L11,0)) -> 0 | BI11: =BF11 -> 5 | BJ11: =IF(BI11="","",VLOOKUP(BI11,Nama_Buku,2)) -> BUKU PEMBANTU UANG PERSEDIAAN | BK11: =IF(E11="D2",L11,IF(E11="H1",L11,IF(E11="H2",L11,IF(E11="J3",L11,IF(E11="K3",L11,IF(E11="N1",L11,IF(E11="N2",L11,0))))))) -> 0 | BL11: 6 | BM11: =IF(BL11="","",VLOOKUP(BL11,Nama_Buku,2)) -> BUKU PEMBANTU LS BENDAHARA | BN11: =IF(E11="C1",L11,IF(E11="C1",L11,IF(E11="R2",L11,IF(E11="L7",L11,0)))) -> 0 | BO11: =BL11 -> 6 | BP11: =IF(BO11="","",VLOOKUP(BO11,Nama_Buku,2)) -> BUKU PEMBANTU LS BENDAHARA | BQ11: =IF(E11="C2",L11,IF(E11="I1",L11,IF(E11="I2",L11,IF(E11="M9",L11,IF(E11="M3",L11,IF(E11="K3",L11,IF(E11="R1",L11,IF(E11="L6",L11,0)))))))) -> 0 | BR11: 7 | BS11: =IF(BR11="","",VLOOKUP(BR11,Nama_Buku,2)) -> BUKU PEMBANTU UANG MUKA PERJADIN | BT11: =IF(E11="K1",L11,IF(E11="K2",L11,0)) -> 0 | BU11: =BR11 -> 7 | BV11: =IF(BU11="","",VLOOKUP(BU11,Nama_Buku,2)) -> BUKU PEMBANTU UANG MUKA PERJADIN | BW11: =IF(E11="K3",L11,IF(E11="K4",L11,0)) -> 0 | BX11: 8 | BY11: =IF(BX11="","",VLOOKUP(BX11,Nama_Buku,2)) -> BUKU PEMBANTU PAJAK UP | BZ11: =IF(E11="M1",L11,IF(E11="M4",L11,IF(E11="M8",L11,0))) -> 0 | CA11: =BX11 -> 8 | CB11: =IF(CA11="","",VLOOKUP(CA11,Nama_Buku,2)) -> BUKU PEMBANTU PAJAK UP | CC11: =IF(E11="M2",L11,IF(E11="M3",L11,IF(E11="M5",L11,0))) -> 0 | CD11: 9 | CE11: =IF(CD11="","",VLOOKUP(CD11,Nama_Buku,2)) -> BUKU PEMBANTU BUNGA REKENING | CF11: =IF(E11="L1",L11,IF(E11="R1",L11,0)) -> 0 | CG11: =CD11 -> 9 | CH11: =IF(CG11="","",VLOOKUP(CG11,Nama_Buku,2)) -> BUKU PEMBANTU BUNGA REKENING | CI11: =IF(E11="L2",L11,IF(E11="L3",L11,0)) -> 66573.83 | CJ11: 10 | CK11: =IF(CJ11="","",VLOOKUP(CJ11,Nama_Buku,2)) -> BUKU PEMBANTU PAJAK UP & LS | CL11: =IF(E11="M1",L11,IF(E11="M4",L11,IF(E11="M6",L11,IF(E11="M8",L11,0)))) -> 0 | CM11: =CJ11 -> 10 | CN11: =IF(CM11="","",VLOOKUP(CM11,Nama_Buku,2)) -> BUKU PEMBANTU PAJAK UP & LS | CO11: =IF(E11="M2",L11,IF(E11="M3",L11,IF(E11="M5",L11,IF(E11="M7",L11,IF(E11="M9",L11,0))))) -> 0 | CP11: =IF(E11="H1",L11,IF(E11="H2",L11,IF(E11="J3",L11,IF(E11="K3",L11,0)))) -> 0 | CQ11: =IF(E11="H1",M11,IF(E11="H2",M11,IF(E11="J3",M11,0))) -> 0 | CR11: =IF(E11="H1",N11,IF(E11="H2",N11,IF(E11="J3",N11,0))) -> 0 | CS11: 11 | CT11: =IF(CS11="","",VLOOKUP(CS11,Nama_Buku,2)) -> BUKU PENGESAHAN BELANJA | CU11: =IF(E11="C2",L11,IF(E11="I1",L11,IF(E11="I2",L11,IF(E11="K3",L11,IF(E11="M3",L11,IF(E11="M9",L11,0)))))) -> 0 | CV11: =CS11 -> 11 | CW11: =IF(CV11="","",VLOOKUP(CV11,Nama_Buku,2)) -> BUKU PENGESAHAN BELANJA | CX11: =IF(E11="C3",L11,0) -> 0 | CY11: 12 | CZ11: =IF(CY11="","",VLOOKUP(CY11,Nama_Buku,2)) -> BUKU PENGEMBALIAN BELANJA | DA11: =IF(E11="L4",L11,IF(E11="R2",L11,0)) -> 0 | DB11: =CY11 -> 12 | DC11: =IF(DB11="","",VLOOKUP(DB11,Nama_Buku,2)) -> BUKU PENGEMBALIAN BELANJA | DD11: =IF(E11="L5",L11,IF(E11="L5",L11,0)) -> 0
A12: 002 | C12: 46051 | D12: ="2026."&A12 -> 2026.002 | E12: C1 | F12: Menerima transfer dana sesuai Surat Perintah Transfer Dana Tanggal 29 Januari 2026 sebesar Rp. 25.000.000 ke Rekening 2001302885742 RPL 046 BLU APT PRANOTO UTK OPS PENGELUARAN | L12: 25000000 | O12: =IF(E12="A",L12,IF(E12="B",L12,IF(E12="C1",L12,IF(E12="D1",L12,IF(E12="E",L12,IF(E12="F",L12,IF(E12="G1",L12,IF(E12="G2",L12,IF(E12="R1",L12,IF(E12="L4",L12,IF(E12="R2",L12,IF(E12="l7",L12,0)))))))))))) -> 25000000 | P12: =IF(E12="J1",L12,IF(E12="J2",L12,IF(E12="J4",L12,IF(E12="K1",L12,IF(E12="K2",L12,IF(E12="K4",L12,IF(E12="L1",L12,IF(E12="M1",L12,IF(E12="M6",L12,IF(E12="M6",L12,0)))))))))) -> 0 | Q12: =IF(E12="M4",L12,0) -> 0 | R12: 1 | S12: =IF(R12="","",VLOOKUP(R12,Nama_Buku,2)) -> BUKU KAS UMUM | T12: =AVERAGE(O12+P12+Q12) -> 25000000 | U12: =IF(E12="A",L12,IF(E12="C2",L12,IF(E12="D2",L12,IF(E12="E",L12,IF(E12="F",L12,IF(E12="G1",L12,IF(E12="G2",L12,IF(E12="H1",L12,IF(E12="R1",L12,0))))))))) -> 0 | V12: =IF(E12="H2",L12,IF(E12="I1",L12,IF(E12="I2",L12,IF(E12="J1",L12,IF(E12="J2",L12,IF(E12="J3",L12,IF(E12="J4",L12,IF(E12="K1",L12,0)))))))) -> 0 | W12: =IF(E12="K2",L12,IF(E12="K3",L12,IF(E12="K4",L12,IF(E12="L2",L12,IF(E12="L3",L12,IF(E12="M2",L12,IF(E12="M3",L12,IF(E12="M7",L12,IF(E12="L5",L12,IF(E12="L6",L12,0)))))))))) -> 0 | X12: =IF(E12="N1",L12,IF(E12="N2",L12,0)) -> 0 | Y12: =R12 -> 1 | Z12: =IF(Y12="","",VLOOKUP(Y12,Nama_Buku,2)) -> BUKU KAS UMUM | AA12: =AVERAGE(U12+V12+W12+X12) -> 0 | AB12: 10 | AC12: =IF(AB12="","",VLOOKUP(AB12,Nama_Buku,2)) -> BUKU PEMBANTU PAJAK UP & LS | AD12: =IF(E12="B",L12,IF(E12="C1",L12,IF(E12="D1",L12,IF(E12="J1",-L12,IF(E12="J2",-L12,IF(E12="L1",L12,IF(E12="M1",L12,IF(E12="M4",L12,IF(E12="M8",L12,IF(E12="R2",L12,0)))))))))) -> 25000000 | AE12: =IF(E12="K1",-L12,IF(E12="K2",-L12,)) -> 0 | AF12: =AVERAGE(AD12+AE12) -> 25000000 | AG12: =IF(E12="C2",L12,IF(E12="D2",L12,IF(E12="H1",L12,IF(E12="H2",L12,IF(E12="I1",L12,IF(E12="I2",L12,IF(E12="J4",-L12,IF(E12="K4",-L12,0)))))))) -> 0 | AH12: =IF(E12="L2",L12,IF(E12="L3",L12,IF(E12="M2",L12,IF(E12="M3",L12,IF(E12="M5",L12,IF(E12="N1",L12,IF(E12="N2",L12,0))))))) -> 0 | AI12: =AB12 -> 10 | AJ12: =IF(AI12="","",VLOOKUP(AI12,Nama_Buku,2)) -> BUKU PEMBANTU PAJAK UP & LS | AK12: =AVERAGE(AG12+AH12) -> 0 | AL12: 2 | AM12: =IF(AL12="","",VLOOKUP(AL12,Nama_Buku,2)) -> BUKU PEMBANTU KAS TUNAI | AN12: =IF(E12="G1",L12,IF(E12="J4",L12,IF(E12="K4",L12,IF(E12="M1",L12,0)))) -> 0 | AO12: =AL12 -> 2 | AP12: =IF(AO12="","",VLOOKUP(AO12,Nama_Buku,2)) -> BUKU PEMBANTU KAS TUNAI | AQ12: =IF(E12="G2",L12,IF(E12="H1",L12,IF(E12="I1",L12,IF(E12="J1",L12,IF(E12="K1",L12,IF(E12="L2",L12,IF(E12="M2",L12,IF(E12="N1",L12,0)))))))) -> 0 | AR12: 3 | AS12: =IF(AR12="","",VLOOKUP(AR12,Nama_Buku,2)) -> BUKU PEMBANTU BANK | AT12: =IF(E12="B",L12,IF(E12="C1",L12,IF(E12="D1",L12,IF(E12="G2",L12,IF(E12="L1",L12,IF(E12="L4",L12,IF(E12="R2",L12,IF(E12="L7",L12,0)))))))) -> 25000000 | AU12: =IF(E12="C2",L12,IF(E12="D2",L12,IF(E12="G1",L12,IF(E12="H2",L12,IF(E12="I2",L12,IF(E12="J2",L12,IF(E12="K2",L12,IF(E12="L3",L12,IF(E12="L5",L12,IF(E12="L6",L12,0)))))))))) -> 0 | AV12: =IF(E12="M3",L12,IF(E12="N2",L12,IF(E12="M9",L12,0))) -> 0 | AW12: =AR12 -> 3 | AX12: =IF(AW12="","",VLOOKUP(AW12,Nama_Buku,2)) -> BUKU PEMBANTU BANK | AY12: =AVERAGE(AU12+AV12) -> 0 | AZ12: 4 | BA12: =IF(AZ12="","",VLOOKUP(AZ12,Nama_Buku,2)) -> BUKU PEMBANTU BPP | BB12: =IF(E12="J1",L12,IF(E12="J2",L12,IF(E12="M4",L12,0))) -> 0 | BC12: =AZ12 -> 4 | BD12: =IF(BC12="","",VLOOKUP(BC12,Nama_Buku,2)) -> BUKU PEMBANTU BPP | BE12: =IF(E12="J3",L12,IF(E12="J4",L12,IF(E12="M5",L12,0))) -> 0 | BF12: 5 | BG12: =IF(BF12="","",VLOOKUP(BF12,Nama_Buku,2)) -> BUKU PEMBANTU UANG PERSEDIAAN | BH12: =IF(E12="B",L12,IF(E12="D1",L12,0)) -> 0 | BI12: =BF12 -> 5 | BJ12: =IF(BI12="","",VLOOKUP(BI12,Nama_Buku,2)) -> BUKU PEMBANTU UANG PERSEDIAAN | BK12: =IF(E12="D2",L12,IF(E12="H1",L12,IF(E12="H2",L12,IF(E12="J3",L12,IF(E12="K3",L12,IF(E12="N1",L12,IF(E12="N2",L12,0))))))) -> 0 | BL12: 6 | BM12: =IF(BL12="","",VLOOKUP(BL12,Nama_Buku,2)) -> BUKU PEMBANTU LS BENDAHARA | BN12: =IF(E12="C1",L12,IF(E12="C1",L12,IF(E12="R2",L12,IF(E12="L7",L12,0)))) -> 25000000 | BO12: =BL12 -> 6 | BP12: =IF(BO12="","",VLOOKUP(BO12,Nama_Buku,2)) -> BUKU PEMBANTU LS BENDAHARA | BQ12: =IF(E12="C2",L12,IF(E12="I1",L12,IF(E12="I2",L12,IF(E12="M9",L12,IF(E12="M3",L12,IF(E12="K3",L12,IF(E12="R1",L12,IF(E12="L6",L12,0)))))))) -> 0 | BR12: 7 | BS12: =IF(BR12="","",VLOOKUP(BR12,Nama_Buku,2)) -> BUKU PEMBANTU UANG MUKA PERJADIN | BT12: =IF(E12="K1",L12,IF(E12="K2",L12,0)) -> 0 | BU12: =BR12 -> 7 | BV12: =IF(BU12="","",VLOOKUP(BU12,Nama_Buku,2)) -> BUKU PEMBANTU UANG MUKA PERJADIN | BW12: =IF(E12="K3",L12,IF(E12="K4",L12,0)) -> 0 | BX12: 8 | BY12: =IF(BX12="","",VLOOKUP(BX12,Nama_Buku,2)) -> BUKU PEMBANTU PAJAK UP | BZ12: =IF(E12="M1",L12,IF(E12="M4",L12,IF(E12="M8",L12,0))) -> 0 | CA12: =BX12 -> 8 | CB12: =IF(CA12="","",VLOOKUP(CA12,Nama_Buku,2)) -> BUKU PEMBANTU PAJAK UP | CC12: =IF(E12="M2",L12,IF(E12="M3",L12,IF(E12="M5",L12,0))) -> 0 | CD12: 9 | CE12: =IF(CD12="","",VLOOKUP(CD12,Nama_Buku,2)) -> BUKU PEMBANTU BUNGA REKENING | CF12: =IF(E12="L1",L12,IF(E12="R1",L12,0)) -> 0 | CG12: =CD12 -> 9 | CH12: =IF(CG12="","",VLOOKUP(CG12,Nama_Buku,2)) -> BUKU PEMBANTU BUNGA REKENING | CI12: =IF(E12="L2",L12,IF(E12="L3",L12,0)) -> 0 | CJ12: 10 | CK12: =IF(CJ12="","",VLOOKUP(CJ12,Nama_Buku,2)) -> BUKU PEMBANTU PAJAK UP & LS | CL12: =IF(E12="M1",L12,IF(E12="M4",L12,IF(E12="M6",L12,IF(E12="M8",L12,0)))) -> 0 | CM12: =CJ12 -> 10 | CN12: =IF(CM12="","",VLOOKUP(CM12,Nama_Buku,2)) -> BUKU PEMBANTU PAJAK UP & LS | CO12: =IF(E12="M2",L12,IF(E12="M3",L12,IF(E12="M5",L12,IF(E12="M7",L12,IF(E12="M9",L12,0))))) -> 0 | CP12: =IF(E12="H1",L12,IF(E12="H2",L12,IF(E12="J3",L12,IF(E12="K3",L12,0)))) -> 0 | CQ12: =IF(E12="H1",M12,IF(E12="H2",M12,IF(E12="J3",M12,0))) -> 0 | CR12: =IF(E12="H1",N12,IF(E12="H2",N12,IF(E12="J3",N12,0))) -> 0 | CS12: 11 | CT12: =IF(CS12="","",VLOOKUP(CS12,Nama_Buku,2)) -> BUKU PENGESAHAN BELANJA | CU12: =IF(E12="C2",L12,IF(E12="I1",L12,IF(E12="I2",L12,IF(E12="K3",L12,IF(E12="M3",L12,IF(E12="M9",L12,0)))))) -> 0 | CV12: =CS12 -> 11 | CW12: =IF(CV12="","",VLOOKUP(CV12,Nama_Buku,2)) -> BUKU PENGESAHAN BELANJA | CX12: =IF(E12="C3",L12,0) -> 0 | CY12: 12 | CZ12: =IF(CY12="","",VLOOKUP(CY12,Nama_Buku,2)) -> BUKU PENGEMBALIAN BELANJA | DA12: =IF(E12="L4",L12,IF(E12="R2",L12,0)) -> 0 | DB12: =CY12 -> 12 | DC12: =IF(DB12="","",VLOOKUP(DB12,Nama_Buku,2)) -> BUKU PENGEMBALIAN BELANJA | DD12: =IF(E12="L5",L12,IF(E12="L5",L12,0)) -> 0
A13: 003 | C13: 46051 | D13: ="2026."&A13 -> 2026.003 | E13: C1 | F13: Menerima transfer dana sesuai Surat Perintah Transfer Dana Tanggal 29 Januari 2026 sebesar Rp. 35.964.000 ke Rekening 2001302885742 RPL 046 BLU APT PRANOTO UTK OPS PENGELUARAN | L13: 35964000 | O13: =IF(E13="A",L13,IF(E13="B",L13,IF(E13="C1",L13,IF(E13="D1",L13,IF(E13="E",L13,IF(E13="F",L13,IF(E13="G1",L13,IF(E13="G2",L13,IF(E13="R1",L13,IF(E13="L4",L13,IF(E13="R2",L13,IF(E13="l7",L13,0)))))))))))) -> 35964000 | P13: =IF(E13="J1",L13,IF(E13="J2",L13,IF(E13="J4",L13,IF(E13="K1",L13,IF(E13="K2",L13,IF(E13="K4",L13,IF(E13="L1",L13,IF(E13="M1",L13,IF(E13="M6",L13,IF(E13="M6",L13,0)))))))))) -> 0 | Q13: =IF(E13="M4",L13,0) -> 0 | R13: 1 | S13: =IF(R13="","",VLOOKUP(R13,Nama_Buku,2)) -> BUKU KAS UMUM | T13: =AVERAGE(O13+P13+Q13) -> 35964000 | U13: =IF(E13="A",L13,IF(E13="C2",L13,IF(E13="D2",L13,IF(E13="E",L13,IF(E13="F",L13,IF(E13="G1",L13,IF(E13="G2",L13,IF(E13="H1",L13,IF(E13="R1",L13,0))))))))) -> 0 | V13: =IF(E13="H2",L13,IF(E13="I1",L13,IF(E13="I2",L13,IF(E13="J1",L13,IF(E13="J2",L13,IF(E13="J3",L13,IF(E13="J4",L13,IF(E13="K1",L13,0)))))))) -> 0 | W13: =IF(E13="K2",L13,IF(E13="K3",L13,IF(E13="K4",L13,IF(E13="L2",L13,IF(E13="L3",L13,IF(E13="M2",L13,IF(E13="M3",L13,IF(E13="M7",L13,IF(E13="L5",L13,IF(E13="L6",L13,0)))))))))) -> 0 | X13: =IF(E13="N1",L13,IF(E13="N2",L13,0)) -> 0 | Y13: =R13 -> 1 | Z13: =IF(Y13="","",VLOOKUP(Y13,Nama_Buku,2)) -> BUKU KAS UMUM | AA13: =AVERAGE(U13+V13+W13+X13) -> 0 | AB13: 10 | AC13: =IF(AB13="","",VLOOKUP(AB13,Nama_Buku,2)) -> BUKU PEMBANTU PAJAK UP & LS | AD13: =IF(E13="B",L13,IF(E13="C1",L13,IF(E13="D1",L13,IF(E13="J1",-L13,IF(E13="J2",-L13,IF(E13="L1",L13,IF(E13="M1",L13,IF(E13="M4",L13,IF(E13="M8",L13,IF(E13="R2",L13,0)))))))))) -> 35964000 | AE13: =IF(E13="K1",-L13,IF(E13="K2",-L13,)) -> 0 | AF13: =AVERAGE(AD13+AE13) -> 35964000 | AG13: =IF(E13="C2",L13,IF(E13="D2",L13,IF(E13="H1",L13,IF(E13="H2",L13,IF(E13="I1",L13,IF(E13="I2",L13,IF(E13="J4",-L13,IF(E13="K4",-L13,0)))))))) -> 0 | AH13: =IF(E13="L2",L13,IF(E13="L3",L13,IF(E13="M2",L13,IF(E13="M3",L13,IF(E13="M5",L13,IF(E13="N1",L13,IF(E13="N2",L13,0))))))) -> 0 | AI13: =AB13 -> 10 | AJ13: =IF(AI13="","",VLOOKUP(AI13,Nama_Buku,2)) -> BUKU PEMBANTU PAJAK UP & LS | AK13: =AVERAGE(AG13+AH13) -> 0 | AL13: 2 | AM13: =IF(AL13="","",VLOOKUP(AL13,Nama_Buku,2)) -> BUKU PEMBANTU KAS TUNAI | AN13: =IF(E13="G1",L13,IF(E13="J4",L13,IF(E13="K4",L13,IF(E13="M1",L13,0)))) -> 0 | AO13: =AL13 -> 2 | AP13: =IF(AO13="","",VLOOKUP(AO13,Nama_Buku,2)) -> BUKU PEMBANTU KAS TUNAI | AQ13: =IF(E13="G2",L13,IF(E13="H1",L13,IF(E13="I1",L13,IF(E13="J1",L13,IF(E13="K1",L13,IF(E13="L2",L13,IF(E13="M2",L13,IF(E13="N1",L13,0)))))))) -> 0 | AR13: 3 | AS13: =IF(AR13="","",VLOOKUP(AR13,Nama_Buku,2)) -> BUKU PEMBANTU BANK | AT13: =IF(E13="B",L13,IF(E13="C1",L13,IF(E13="D1",L13,IF(E13="G2",L13,IF(E13="L1",L13,IF(E13="L4",L13,IF(E13="R2",L13,IF(E13="L7",L13,0)))))))) -> 35964000 | AU13: =IF(E13="C2",L13,IF(E13="D2",L13,IF(E13="G1",L13,IF(E13="H2",L13,IF(E13="I2",L13,IF(E13="J2",L13,IF(E13="K2",L13,IF(E13="L3",L13,IF(E13="L5",L13,IF(E13="L6",L13,0)))))))))) -> 0 | AV13: =IF(E13="M3",L13,IF(E13="N2",L13,IF(E13="M9",L13,0))) -> 0 | AW13: =AR13 -> 3 | AX13: =IF(AW13="","",VLOOKUP(AW13,Nama_Buku,2)) -> BUKU PEMBANTU BANK | AY13: =AVERAGE(AU13+AV13) -> 0 | AZ13: 4 | BA13: =IF(AZ13="","",VLOOKUP(AZ13,Nama_Buku,2)) -> BUKU PEMBANTU BPP | BB13: =IF(E13="J1",L13,IF(E13="J2",L13,IF(E13="M4",L13,0))) -> 0 | BC13: =AZ13 -> 4 | BD13: =IF(BC13="","",VLOOKUP(BC13,Nama_Buku,2)) -> BUKU PEMBANTU BPP | BE13: =IF(E13="J3",L13,IF(E13="J4",L13,IF(E13="M5",L13,0))) -> 0 | BF13: 5 | BG13: =IF(BF13="","",VLOOKUP(BF13,Nama_Buku,2)) -> BUKU PEMBANTU UANG PERSEDIAAN | BH13: =IF(E13="B",L13,IF(E13="D1",L13,0)) -> 0 | BI13: =BF13 -> 5 | BJ13: =IF(BI13="","",VLOOKUP(BI13,Nama_Buku,2)) -> BUKU PEMBANTU UANG PERSEDIAAN | BK13: =IF(E13="D2",L13,IF(E13="H1",L13,IF(E13="H2",L13,IF(E13="J3",L13,IF(E13="K3",L13,IF(E13="N1",L13,IF(E13="N2",L13,0))))))) -> 0 | BL13: 6 | BM13: =IF(BL13="","",VLOOKUP(BL13,Nama_Buku,2)) -> BUKU PEMBANTU LS BENDAHARA | BN13: =IF(E13="C1",L13,IF(E13="C1",L13,IF(E13="R2",L13,IF(E13="L7",L13,0)))) -> 35964000 | BO13: =BL13 -> 6 | BP13: =IF(BO13="","",VLOOKUP(BO13,Nama_Buku,2)) -> BUKU PEMBANTU LS BENDAHARA | BQ13: =IF(E13="C2",L13,IF(E13="I1",L13,IF(E13="I2",L13,IF(E13="M9",L13,IF(E13="M3",L13,IF(E13="K3",L13,IF(E13="R1",L13,IF(E13="L6",L13,0)))))))) -> 0 | BR13: 7 | BS13: =IF(BR13="","",VLOOKUP(BR13,Nama_Buku,2)) -> BUKU PEMBANTU UANG MUKA PERJADIN | BT13: =IF(E13="K1",L13,IF(E13="K2",L13,0)) -> 0 | BU13: =BR13 -> 7 | BV13: =IF(BU13="","",VLOOKUP(BU13,Nama_Buku,2)) -> BUKU PEMBANTU UANG MUKA PERJADIN | BW13: =IF(E13="K3",L13,IF(E13="K4",L13,0)) -> 0 | BX13: 8 | BY13: =IF(BX13="","",VLOOKUP(BX13,Nama_Buku,2)) -> BUKU PEMBANTU PAJAK UP | BZ13: =IF(E13="M1",L13,IF(E13="M4",L13,IF(E13="M8",L13,0))) -> 0 | CA13: =BX13 -> 8 | CB13: =IF(CA13="","",VLOOKUP(CA13,Nama_Buku,2)) -> BUKU PEMBANTU PAJAK UP | CC13: =IF(E13="M2",L13,IF(E13="M3",L13,IF(E13="M5",L13,0))) -> 0 | CD13: 9 | CE13: =IF(CD13="","",VLOOKUP(CD13,Nama_Buku,2)) -> BUKU PEMBANTU BUNGA REKENING | CF13: =IF(E13="L1",L13,IF(E13="R1",L13,0)) -> 0 | CG13: =CD13 -> 9 | CH13: =IF(CG13="","",VLOOKUP(CG13,Nama_Buku,2)) -> BUKU PEMBANTU BUNGA REKENING | CI13: =IF(E13="L2",L13,IF(E13="L3",L13,0)) -> 0 | CJ13: 10 | CK13: =IF(CJ13="","",VLOOKUP(CJ13,Nama_Buku,2)) -> BUKU PEMBANTU PAJAK UP & LS | CL13: =IF(E13="M1",L13,IF(E13="M4",L13,IF(E13="M6",L13,IF(E13="M8",L13,0)))) -> 0 | CM13: =CJ13 -> 10 | CN13: =IF(CM13="","",VLOOKUP(CM13,Nama_Buku,2)) -> BUKU PEMBANTU PAJAK UP & LS | CO13: =IF(E13="M2",L13,IF(E13="M3",L13,IF(E13="M5",L13,IF(E13="M7",L13,IF(E13="M9",L13,0))))) -> 0 | CP13: =IF(E13="H1",L13,IF(E13="H2",L13,IF(E13="J3",L13,IF(E13="K3",L13,0)))) -> 0 | CQ13: =IF(E13="H1",M13,IF(E13="H2",M13,IF(E13="J3",M13,0))) -> 0 | CR13: =IF(E13="H1",N13,IF(E13="H2",N13,IF(E13="J3",N13,0))) -> 0 | CS13: 11 | CT13: =IF(CS13="","",VLOOKUP(CS13,Nama_Buku,2)) -> BUKU PENGESAHAN BELANJA | CU13: =IF(E13="C2",L13,IF(E13="I1",L13,IF(E13="I2",L13,IF(E13="K3",L13,IF(E13="M3",L13,IF(E13="M9",L13,0)))))) -> 0 | CV13: =CS13 -> 11 | CW13: =IF(CV13="","",VLOOKUP(CV13,Nama_Buku,2)) -> BUKU PENGESAHAN BELANJA | CX13: =IF(E13="C3",L13,0) -> 0 | CY13: 12 | CZ13: =IF(CY13="","",VLOOKUP(CY13,Nama_Buku,2)) -> BUKU PENGEMBALIAN BELANJA | DA13: =IF(E13="L4",L13,IF(E13="R2",L13,0)) -> 0 | DB13: =CY13 -> 12 | DC13: =IF(DB13="","",VLOOKUP(DB13,Nama_Buku,2)) -> BUKU PENGEMBALIAN BELANJA | DD13: =IF(E13="L5",L13,IF(E13="L5",L13,0)) -> 0
A14: 004 | C14: 46051 | D14: ="2026."&A14 -> 2026.004 | E14: C1 | F14: Menerima transfer dana sesuai Surat Perintah Transfer Dana Tanggal 29 Januari 2026 sebesar Rp. 26.640.000 ke Rekening 2001302885742 RPL 046 BLU APT PRANOTO UTK OPS PENGELUARAN | L14: 26640000 | O14: =IF(E14="A",L14,IF(E14="B",L14,IF(E14="C1",L14,IF(E14="D1",L14,IF(E14="E",L14,IF(E14="F",L14,IF(E14="G1",L14,IF(E14="G2",L14,IF(E14="R1",L14,IF(E14="L4",L14,IF(E14="R2",L14,IF(E14="l7",L14,0)))))))))))) -> 26640000 | P14: =IF(E14="J1",L14,IF(E14="J2",L14,IF(E14="J4",L14,IF(E14="K1",L14,IF(E14="K2",L14,IF(E14="K4",L14,IF(E14="L1",L14,IF(E14="M1",L14,IF(E14="M6",L14,IF(E14="M6",L14,0)))))))))) -> 0 | Q14: =IF(E14="M4",L14,0) -> 0 | R14: 1 | S14: =IF(R14="","",VLOOKUP(R14,Nama_Buku,2)) -> BUKU KAS UMUM | T14: =AVERAGE(O14+P14+Q14) -> 26640000 | U14: =IF(E14="A",L14,IF(E14="C2",L14,IF(E14="D2",L14,IF(E14="E",L14,IF(E14="F",L14,IF(E14="G1",L14,IF(E14="G2",L14,IF(E14="H1",L14,IF(E14="R1",L14,0))))))))) -> 0 | V14: =IF(E14="H2",L14,IF(E14="I1",L14,IF(E14="I2",L14,IF(E14="J1",L14,IF(E14="J2",L14,IF(E14="J3",L14,IF(E14="J4",L14,IF(E14="K1",L14,0)))))))) -> 0 | W14: =IF(E14="K2",L14,IF(E14="K3",L14,IF(E14="K4",L14,IF(E14="L2",L14,IF(E14="L3",L14,IF(E14="M2",L14,IF(E14="M3",L14,IF(E14="M7",L14,IF(E14="L5",L14,IF(E14="L6",L14,0)))))))))) -> 0 | X14: =IF(E14="N1",L14,IF(E14="N2",L14,0)) -> 0 | Y14: =R14 -> 1 | Z14: =IF(Y14="","",VLOOKUP(Y14,Nama_Buku,2)) -> BUKU KAS UMUM | AA14: =AVERAGE(U14+V14+W14+X14) -> 0 | AB14: 10 | AC14: =IF(AB14="","",VLOOKUP(AB14,Nama_Buku,2)) -> BUKU PEMBANTU PAJAK UP & LS | AD14: =IF(E14="B",L14,IF(E14="C1",L14,IF(E14="D1",L14,IF(E14="J1",-L14,IF(E14="J2",-L14,IF(E14="L1",L14,IF(E14="M1",L14,IF(E14="M4",L14,IF(E14="M8",L14,IF(E14="R2",L14,0)))))))))) -> 26640000 | AE14: =IF(E14="K1",-L14,IF(E14="K2",-L14,)) -> 0 | AF14: =AVERAGE(AD14+AE14) -> 26640000 | AG14: =IF(E14="C2",L14,IF(E14="D2",L14,IF(E14="H1",L14,IF(E14="H2",L14,IF(E14="I1",L14,IF(E14="I2",L14,IF(E14="J4",-L14,IF(E14="K4",-L14,0)))))))) -> 0 | AH14: =IF(E14="L2",L14,IF(E14="L3",L14,IF(E14="M2",L14,IF(E14="M3",L14,IF(E14="M5",L14,IF(E14="N1",L14,IF(E14="N2",L14,0))))))) -> 0 | AI14: =AB14 -> 10 | AJ14: =IF(AI14="","",VLOOKUP(AI14,Nama_Buku,2)) -> BUKU PEMBANTU PAJAK UP & LS | AK14: =AVERAGE(AG14+AH14) -> 0 | AL14: 2 | AM14: =IF(AL14="","",VLOOKUP(AL14,Nama_Buku,2)) -> BUKU PEMBANTU KAS TUNAI | AN14: =IF(E14="G1",L14,IF(E14="J4",L14,IF(E14="K4",L14,IF(E14="M1",L14,0)))) -> 0 | AO14: =AL14 -> 2 | AP14: =IF(AO14="","",VLOOKUP(AO14,Nama_Buku,2)) -> BUKU PEMBANTU KAS TUNAI | AQ14: =IF(E14="G2",L14,IF(E14="H1",L14,IF(E14="I1",L14,IF(E14="J1",L14,IF(E14="K1",L14,IF(E14="L2",L14,IF(E14="M2",L14,IF(E14="N1",L14,0)))))))) -> 0 | AR14: 3 | AS14: =IF(AR14="","",VLOOKUP(AR14,Nama_Buku,2)) -> BUKU PEMBANTU BANK | AT14: =IF(E14="B",L14,IF(E14="C1",L14,IF(E14="D1",L14,IF(E14="G2",L14,IF(E14="L1",L14,IF(E14="L4",L14,IF(E14="R2",L14,IF(E14="L7",L14,0)))))))) -> 26640000 | AU14: =IF(E14="C2",L14,IF(E14="D2",L14,IF(E14="G1",L14,IF(E14="H2",L14,IF(E14="I2",L14,IF(E14="J2",L14,IF(E14="K2",L14,IF(E14="L3",L14,IF(E14="L5",L14,IF(E14="L6",L14,0)))))))))) -> 0 | AV14: =IF(E14="M3",L14,IF(E14="N2",L14,IF(E14="M9",L14,0))) -> 0 | AW14: =AR14 -> 3 | AX14: =IF(AW14="","",VLOOKUP(AW14,Nama_Buku,2)) -> BUKU PEMBANTU BANK | AY14: =AVERAGE(AU14+AV14) -> 0 | AZ14: 4 | BA14: =IF(AZ14="","",VLOOKUP(AZ14,Nama_Buku,2)) -> BUKU PEMBANTU BPP | BB14: =IF(E14="J1",L14,IF(E14="J2",L14,IF(E14="M4",L14,0))) -> 0 | BC14: =AZ14 -> 4 | BD14: =IF(BC14="","",VLOOKUP(BC14,Nama_Buku,2)) -> BUKU PEMBANTU BPP | BE14: =IF(E14="J3",L14,IF(E14="J4",L14,IF(E14="M5",L14,0))) -> 0 | BF14: 5 | BG14: =IF(BF14="","",VLOOKUP(BF14,Nama_Buku,2)) -> BUKU PEMBANTU UANG PERSEDIAAN | BH14: =IF(E14="B",L14,IF(E14="D1",L14,0)) -> 0 | BI14: =BF14 -> 5 | BJ14: =IF(BI14="","",VLOOKUP(BI14,Nama_Buku,2)) -> BUKU PEMBANTU UANG PERSEDIAAN | BK14: =IF(E14="D2",L14,IF(E14="H1",L14,IF(E14="H2",L14,IF(E14="J3",L14,IF(E14="K3",L14,IF(E14="N1",L14,IF(E14="N2",L14,0))))))) -> 0 | BL14: 6 | BM14: =IF(BL14="","",VLOOKUP(BL14,Nama_Buku,2)) -> BUKU PEMBANTU LS BENDAHARA | BN14: =IF(E14="C1",L14,IF(E14="C1",L14,IF(E14="R2",L14,IF(E14="L7",L14,0)))) -> 26640000 | BO14: =BL14 -> 6 | BP14: =IF(BO14="","",VLOOKUP(BO14,Nama_Buku,2)) -> BUKU PEMBANTU LS BENDAHARA | BQ14: =IF(E14="C2",L14,IF(E14="I1",L14,IF(E14="I2",L14,IF(E14="M9",L14,IF(E14="M3",L14,IF(E14="K3",L14,IF(E14="R1",L14,IF(E14="L6",L14,0)))))))) -> 0 | BR14: 7 | BS14: =IF(BR14="","",VLOOKUP(BR14,Nama_Buku,2)) -> BUKU PEMBANTU UANG MUKA PERJADIN | BT14: =IF(E14="K1",L14,IF(E14="K2",L14,0)) -> 0 | BU14: =BR14 -> 7 | BV14: =IF(BU14="","",VLOOKUP(BU14,Nama_Buku,2)) -> BUKU PEMBANTU UANG MUKA PERJADIN | BW14: =IF(E14="K3",L14,IF(E14="K4",L14,0)) -> 0 | BX14: 8 | BY14: =IF(BX14="","",VLOOKUP(BX14,Nama_Buku,2)) -> BUKU PEMBANTU PAJAK UP | BZ14: =IF(E14="M1",L14,IF(E14="M4",L14,IF(E14="M8",L14,0))) -> 0 | CA14: =BX14 -> 8 | CB14: =IF(CA14="","",VLOOKUP(CA14,Nama_Buku,2)) -> BUKU PEMBANTU PAJAK UP | CC14: =IF(E14="M2",L14,IF(E14="M3",L14,IF(E14="M5",L14,0))) -> 0 | CD14: 9 | CE14: =IF(CD14="","",VLOOKUP(CD14,Nama_Buku,2)) -> BUKU PEMBANTU BUNGA REKENING | CF14: =IF(E14="L1",L14,IF(E14="R1",L14,0)) -> 0 | CG14: =CD14 -> 9 | CH14: =IF(CG14="","",VLOOKUP(CG14,Nama_Buku,2)) -> BUKU PEMBANTU BUNGA REKENING | CI14: =IF(E14="L2",L14,IF(E14="L3",L14,0)) -> 0 | CJ14: 10 | CK14: =IF(CJ14="","",VLOOKUP(CJ14,Nama_Buku,2)) -> BUKU PEMBANTU PAJAK UP & LS | CL14: =IF(E14="M1",L14,IF(E14="M4",L14,IF(E14="M6",L14,IF(E14="M8",L14,0)))) -> 0 | CM14: =CJ14 -> 10 | CN14: =IF(CM14="","",VLOOKUP(CM14,Nama_Buku,2)) -> BUKU PEMBANTU PAJAK UP & LS | CO14: =IF(E14="M2",L14,IF(E14="M3",L14,IF(E14="M5",L14,IF(E14="M7",L14,IF(E14="M9",L14,0))))) -> 0 | CP14: =IF(E14="H1",L14,IF(E14="H2",L14,IF(E14="J3",L14,IF(E14="K3",L14,0)))) -> 0 | CQ14: =IF(E14="H1",M14,IF(E14="H2",M14,IF(E14="J3",M14,0))) -> 0 | CR14: =IF(E14="H1",N14,IF(E14="H2",N14,IF(E14="J3",N14,0))) -> 0 | CS14: 11 | CT14: =IF(CS14="","",VLOOKUP(CS14,Nama_Buku,2)) -> BUKU PENGESAHAN BELANJA | CU14: =IF(E14="C2",L14,IF(E14="I1",L14,IF(E14="I2",L14,IF(E14="K3",L14,IF(E14="M3",L14,IF(E14="M9",L14,0)))))) -> 0 | CV14: =CS14 -> 11 | CW14: =IF(CV14="","",VLOOKUP(CV14,Nama_Buku,2)) -> BUKU PENGESAHAN BELANJA | CX14: =IF(E14="C3",L14,0) -> 0 | CY14: 12 | CZ14: =IF(CY14="","",VLOOKUP(CY14,Nama_Buku,2)) -> BUKU PENGEMBALIAN BELANJA | DA14: =IF(E14="L4",L14,IF(E14="R2",L14,0)) -> 0 | DB14: =CY14 -> 12 | DC14: =IF(DB14="","",VLOOKUP(DB14,Nama_Buku,2)) -> BUKU PENGEMBALIAN BELANJA | DD14: =IF(E14="L5",L14,IF(E14="L5",L14,0)) -> 0
A15: 005 | C15: 46051 | D15: ="2026."&A15 -> 2026.005 | E15: C1 | F15: Menerima transfer dana sesuai Surat Perintah Transfer Dana Tanggal 29 Januari 2026 sebesar Rp. 10.989.000 ke Rekening 2001302885742 RPL 046 BLU APT PRANOTO UTK OPS PENGELUARAN | L15: 10989000 | O15: =IF(E15="A",L15,IF(E15="B",L15,IF(E15="C1",L15,IF(E15="D1",L15,IF(E15="E",L15,IF(E15="F",L15,IF(E15="G1",L15,IF(E15="G2",L15,IF(E15="R1",L15,IF(E15="L4",L15,IF(E15="R2",L15,IF(E15="l7",L15,0)))))))))))) -> 10989000 | P15: =IF(E15="J1",L15,IF(E15="J2",L15,IF(E15="J4",L15,IF(E15="K1",L15,IF(E15="K2",L15,IF(E15="K4",L15,IF(E15="L1",L15,IF(E15="M1",L15,IF(E15="M6",L15,IF(E15="M6",L15,0)))))))))) -> 0 | Q15: =IF(E15="M4",L15,0) -> 0 | R15: 1 | S15: =IF(R15="","",VLOOKUP(R15,Nama_Buku,2)) -> BUKU KAS UMUM | T15: =AVERAGE(O15+P15+Q15) -> 10989000 | U15: =IF(E15="A",L15,IF(E15="C2",L15,IF(E15="D2",L15,IF(E15="E",L15,IF(E15="F",L15,IF(E15="G1",L15,IF(E15="G2",L15,IF(E15="H1",L15,IF(E15="R1",L15,0))))))))) -> 0 | V15: =IF(E15="H2",L15,IF(E15="I1",L15,IF(E15="I2",L15,IF(E15="J1",L15,IF(E15="J2",L15,IF(E15="J3",L15,IF(E15="J4",L15,IF(E15="K1",L15,0)))))))) -> 0 | W15: =IF(E15="K2",L15,IF(E15="K3",L15,IF(E15="K4",L15,IF(E15="L2",L15,IF(E15="L3",L15,IF(E15="M2",L15,IF(E15="M3",L15,IF(E15="M7",L15,IF(E15="L5",L15,IF(E15="L6",L15,0)))))))))) -> 0 | X15: =IF(E15="N1",L15,IF(E15="N2",L15,0)) -> 0 | Y15: =R15 -> 1 | Z15: =IF(Y15="","",VLOOKUP(Y15,Nama_Buku,2)) -> BUKU KAS UMUM | AA15: =AVERAGE(U15+V15+W15+X15) -> 0 | AB15: 10 | AC15: =IF(AB15="","",VLOOKUP(AB15,Nama_Buku,2)) -> BUKU PEMBANTU PAJAK UP & LS | AD15: =IF(E15="B",L15,IF(E15="C1",L15,IF(E15="D1",L15,IF(E15="J1",-L15,IF(E15="J2",-L15,IF(E15="L1",L15,IF(E15="M1",L15,IF(E15="M4",L15,IF(E15="M8",L15,IF(E15="R2",L15,0)))))))))) -> 10989000 | AE15: =IF(E15="K1",-L15,IF(E15="K2",-L15,)) -> 0 | AF15: =AVERAGE(AD15+AE15) -> 10989000 | AG15: =IF(E15="C2",L15,IF(E15="D2",L15,IF(E15="H1",L15,IF(E15="H2",L15,IF(E15="I1",L15,IF(E15="I2",L15,IF(E15="J4",-L15,IF(E15="K4",-L15,0)))))))) -> 0 | AH15: =IF(E15="L2",L15,IF(E15="L3",L15,IF(E15="M2",L15,IF(E15="M3",L15,IF(E15="M5",L15,IF(E15="N1",L15,IF(E15="N2",L15,0))))))) -> 0 | AI15: =AB15 -> 10 | AJ15: =IF(AI15="","",VLOOKUP(AI15,Nama_Buku,2)) -> BUKU PEMBANTU PAJAK UP & LS | AK15: =AVERAGE(AG15+AH15) -> 0 | AL15: 2 | AM15: =IF(AL15="","",VLOOKUP(AL15,Nama_Buku,2)) -> BUKU PEMBANTU KAS TUNAI | AN15: =IF(E15="G1",L15,IF(E15="J4",L15,IF(E15="K4",L15,IF(E15="M1",L15,0)))) -> 0 | AO15: =AL15 -> 2 | AP15: =IF(AO15="","",VLOOKUP(AO15,Nama_Buku,2)) -> BUKU PEMBANTU KAS TUNAI | AQ15: =IF(E15="G2",L15,IF(E15="H1",L15,IF(E15="I1",L15,IF(E15="J1",L15,IF(E15="K1",L15,IF(E15="L2",L15,IF(E15="M2",L15,IF(E15="N1",L15,0)))))))) -> 0 | AR15: 3 | AS15: =IF(AR15="","",VLOOKUP(AR15,Nama_Buku,2)) -> BUKU PEMBANTU BANK | AT15: =IF(E15="B",L15,IF(E15="C1",L15,IF(E15="D1",L15,IF(E15="G2",L15,IF(E15="L1",L15,IF(E15="L4",L15,IF(E15="R2",L15,IF(E15="L7",L15,0)))))))) -> 10989000 | AU15: =IF(E15="C2",L15,IF(E15="D2",L15,IF(E15="G1",L15,IF(E15="H2",L15,IF(E15="I2",L15,IF(E15="J2",L15,IF(E15="K2",L15,IF(E15="L3",L15,IF(E15="L5",L15,IF(E15="L6",L15,0)))))))))) -> 0 | AV15: =IF(E15="M3",L15,IF(E15="N2",L15,IF(E15="M9",L15,0))) -> 0 | AW15: =AR15 -> 3 | AX15: =IF(AW15="","",VLOOKUP(AW15,Nama_Buku,2)) -> BUKU PEMBANTU BANK | AY15: =AVERAGE(AU15+AV15) -> 0 | AZ15: 4 | BA15: =IF(AZ15="","",VLOOKUP(AZ15,Nama_Buku,2)) -> BUKU PEMBANTU BPP | BB15: =IF(E15="J1",L15,IF(E15="J2",L15,IF(E15="M4",L15,0))) -> 0 | BC15: =AZ15 -> 4 | BD15: =IF(BC15="","",VLOOKUP(BC15,Nama_Buku,2)) -> BUKU PEMBANTU BPP | BE15: =IF(E15="J3",L15,IF(E15="J4",L15,IF(E15="M5",L15,0))) -> 0 | BF15: 5 | BG15: =IF(BF15="","",VLOOKUP(BF15,Nama_Buku,2)) -> BUKU PEMBANTU UANG PERSEDIAAN | BH15: =IF(E15="B",L15,IF(E15="D1",L15,0)) -> 0 | BI15: =BF15 -> 5 | BJ15: =IF(BI15="","",VLOOKUP(BI15,Nama_Buku,2)) -> BUKU PEMBANTU UANG PERSEDIAAN | BK15: =IF(E15="D2",L15,IF(E15="H1",L15,IF(E15="H2",L15,IF(E15="J3",L15,IF(E15="K3",L15,IF(E15="N1",L15,IF(E15="N2",L15,0))))))) -> 0 | BL15: 6 | BM15: =IF(BL15="","",VLOOKUP(BL15,Nama_Buku,2)) -> BUKU PEMBANTU LS BENDAHARA | BN15: =IF(E15="C1",L15,IF(E15="C1",L15,IF(E15="R2",L15,IF(E15="L7",L15,0)))) -> 10989000 | BO15: =BL15 -> 6 | BP15: =IF(BO15="","",VLOOKUP(BO15,Nama_Buku,2)) -> BUKU PEMBANTU LS BENDAHARA | BQ15: =IF(E15="C2",L15,IF(E15="I1",L15,IF(E15="I2",L15,IF(E15="M9",L15,IF(E15="M3",L15,IF(E15="K3",L15,IF(E15="R1",L15,IF(E15="L6",L15,0)))))))) -> 0 | BR15: 7 | BS15: =IF(BR15="","",VLOOKUP(BR15,Nama_Buku,2)) -> BUKU PEMBANTU UANG MUKA PERJADIN | BT15: =IF(E15="K1",L15,IF(E15="K2",L15,0)) -> 0 | BU15: =BR15 -> 7 | BV15: =IF(BU15="","",VLOOKUP(BU15,Nama_Buku,2)) -> BUKU PEMBANTU UANG MUKA PERJADIN | BW15: =IF(E15="K3",L15,IF(E15="K4",L15,0)) -> 0 | BX15: 8 | BY15: =IF(BX15="","",VLOOKUP(BX15,Nama_Buku,2)) -> BUKU PEMBANTU PAJAK UP | BZ15: =IF(E15="M1",L15,IF(E15="M4",L15,IF(E15="M8",L15,0))) -> 0 | CA15: =BX15 -> 8 | CB15: =IF(CA15="","",VLOOKUP(CA15,Nama_Buku,2)) -> BUKU PEMBANTU PAJAK UP | CC15: =IF(E15="M2",L15,IF(E15="M3",L15,IF(E15="M5",L15,0))) -> 0 | CD15: 9 | CE15: =IF(CD15="","",VLOOKUP(CD15,Nama_Buku,2)) -> BUKU PEMBANTU BUNGA REKENING | CF15: =IF(E15="L1",L15,IF(E15="R1",L15,0)) -> 0 | CG15: =CD15 -> 9 | CH15: =IF(CG15="","",VLOOKUP(CG15,Nama_Buku,2)) -> BUKU PEMBANTU BUNGA REKENING | CI15: =IF(E15="L2",L15,IF(E15="L3",L15,0)) -> 0 | CJ15: 10 | CK15: =IF(CJ15="","",VLOOKUP(CJ15,Nama_Buku,2)) -> BUKU PEMBANTU PAJAK UP & LS | CL15: =IF(E15="M1",L15,IF(E15="M4",L15,IF(E15="M6",L15,IF(E15="M8",L15,0)))) -> 0 | CM15: =CJ15 -> 10 | CN15: =IF(CM15="","",VLOOKUP(CM15,Nama_Buku,2)) -> BUKU PEMBANTU PAJAK UP & LS | CO15: =IF(E15="M2",L15,IF(E15="M3",L15,IF(E15="M5",L15,IF(E15="M7",L15,IF(E15="M9",L15,0))))) -> 0 | CP15: =IF(E15="H1",L15,IF(E15="H2",L15,IF(E15="J3",L15,IF(E15="K3",L15,0)))) -> 0 | CQ15: =IF(E15="H1",M15,IF(E15="H2",M15,IF(E15="J3",M15,0))) -> 0 | CR15: =IF(E15="H1",N15,IF(E15="H2",N15,IF(E15="J3",N15,0))) -> 0 | CS15: 11 | CT15: =IF(CS15="","",VLOOKUP(CS15,Nama_Buku,2)) -> BUKU PENGESAHAN BELANJA | CU15: =IF(E15="C2",L15,IF(E15="I1",L15,IF(E15="I2",L15,IF(E15="K3",L15,IF(E15="M3",L15,IF(E15="M9",L15,0)))))) -> 0 | CV15: =CS15 -> 11 | CW15: =IF(CV15="","",VLOOKUP(CV15,Nama_Buku,2)) -> BUKU PENGESAHAN BELANJA | CX15: =IF(E15="C3",L15,0) -> 0 | CY15: 12 | CZ15: =IF(CY15="","",VLOOKUP(CY15,Nama_Buku,2)) -> BUKU PENGEMBALIAN BELANJA | DA15: =IF(E15="L4",L15,IF(E15="R2",L15,0)) -> 0 | DB15: =CY15 -> 12 | DC15: =IF(DB15="","",VLOOKUP(DB15,Nama_Buku,2)) -> BUKU PENGEMBALIAN BELANJA | DD15: =IF(E15="L5",L15,IF(E15="L5",L15,0)) -> 0
A16: 006 | C16: 46051 | D16: ="2026."&A16 -> 2026.006 | E16: C1 | F16: Menerima transfer dana sesuai Surat Perintah Transfer Dana Tanggal 29 Januari 2026 sebesar Rp. 35.520.000 ke Rekening 2001302885742 RPL 046 BLU APT PRANOTO UTK OPS PENGELUARAN | L16: 35520000 | O16: =IF(E16="A",L16,IF(E16="B",L16,IF(E16="C1",L16,IF(E16="D1",L16,IF(E16="E",L16,IF(E16="F",L16,IF(E16="G1",L16,IF(E16="G2",L16,IF(E16="R1",L16,IF(E16="L4",L16,IF(E16="R2",L16,IF(E16="l7",L16,0)))))))))))) -> 35520000 | P16: =IF(E16="J1",L16,IF(E16="J2",L16,IF(E16="J4",L16,IF(E16="K1",L16,IF(E16="K2",L16,IF(E16="K4",L16,IF(E16="L1",L16,IF(E16="M1",L16,IF(E16="M6",L16,IF(E16="M6",L16,0)))))))))) -> 0 | Q16: =IF(E16="M4",L16,0) -> 0 | R16: 1 | S16: =IF(R16="","",VLOOKUP(R16,Nama_Buku,2)) -> BUKU KAS UMUM | T16: =AVERAGE(O16+P16+Q16) -> 35520000 | U16: =IF(E16="A",L16,IF(E16="C2",L16,IF(E16="D2",L16,IF(E16="E",L16,IF(E16="F",L16,IF(E16="G1",L16,IF(E16="G2",L16,IF(E16="H1",L16,IF(E16="R1",L16,0))))))))) -> 0 | V16: =IF(E16="H2",L16,IF(E16="I1",L16,IF(E16="I2",L16,IF(E16="J1",L16,IF(E16="J2",L16,IF(E16="J3",L16,IF(E16="J4",L16,IF(E16="K1",L16,0)))))))) -> 0 | W16: =IF(E16="K2",L16,IF(E16="K3",L16,IF(E16="K4",L16,IF(E16="L2",L16,IF(E16="L3",L16,IF(E16="M2",L16,IF(E16="M3",L16,IF(E16="M7",L16,IF(E16="L5",L16,IF(E16="L6",L16,0)))))))))) -> 0 | X16: =IF(E16="N1",L16,IF(E16="N2",L16,0)) -> 0 | Y16: =R16 -> 1 | Z16: =IF(Y16="","",VLOOKUP(Y16,Nama_Buku,2)) -> BUKU KAS UMUM | AA16: =AVERAGE(U16+V16+W16+X16) -> 0 | AB16: 10 | AC16: =IF(AB16="","",VLOOKUP(AB16,Nama_Buku,2)) -> BUKU PEMBANTU PAJAK UP & LS | AD16: =IF(E16="B",L16,IF(E16="C1",L16,IF(E16="D1",L16,IF(E16="J1",-L16,IF(E16="J2",-L16,IF(E16="L1",L16,IF(E16="M1",L16,IF(E16="M4",L16,IF(E16="M8",L16,IF(E16="R2",L16,0)))))))))) -> 35520000 | AE16: =IF(E16="K1",-L16,IF(E16="K2",-L16,)) -> 0 | AF16: =AVERAGE(AD16+AE16) -> 35520000 | AG16: =IF(E16="C2",L16,IF(E16="D2",L16,IF(E16="H1",L16,IF(E16="H2",L16,IF(E16="I1",L16,IF(E16="I2",L16,IF(E16="J4",-L16,IF(E16="K4",-L16,0)))))))) -> 0 | AH16: =IF(E16="L2",L16,IF(E16="L3",L16,IF(E16="M2",L16,IF(E16="M3",L16,IF(E16="M5",L16,IF(E16="N1",L16,IF(E16="N2",L16,0))))))) -> 0 | AI16: =AB16 -> 10 | AJ16: =IF(AI16="","",VLOOKUP(AI16,Nama_Buku,2)) -> BUKU PEMBANTU PAJAK UP & LS | AK16: =AVERAGE(AG16+AH16) -> 0 | AL16: 2 | AM16: =IF(AL16="","",VLOOKUP(AL16,Nama_Buku,2)) -> BUKU PEMBANTU KAS TUNAI | AN16: =IF(E16="G1",L16,IF(E16="J4",L16,IF(E16="K4",L16,IF(E16="M1",L16,0)))) -> 0 | AO16: =AL16 -> 2 | AP16: =IF(AO16="","",VLOOKUP(AO16,Nama_Buku,2)) -> BUKU PEMBANTU KAS TUNAI | AQ16: =IF(E16="G2",L16,IF(E16="H1",L16,IF(E16="I1",L16,IF(E16="J1",L16,IF(E16="K1",L16,IF(E16="L2",L16,IF(E16="M2",L16,IF(E16="N1",L16,0)))))))) -> 0 | AR16: 3 | AS16: =IF(AR16="","",VLOOKUP(AR16,Nama_Buku,2)) -> BUKU PEMBANTU BANK | AT16: =IF(E16="B",L16,IF(E16="C1",L16,IF(E16="D1",L16,IF(E16="G2",L16,IF(E16="L1",L16,IF(E16="L4",L16,IF(E16="R2",L16,IF(E16="L7",L16,0)))))))) -> 35520000 | AU16: =IF(E16="C2",L16,IF(E16="D2",L16,IF(E16="G1",L16,IF(E16="H2",L16,IF(E16="I2",L16,IF(E16="J2",L16,IF(E16="K2",L16,IF(E16="L3",L16,IF(E16="L5",L16,IF(E16="L6",L16,0)))))))))) -> 0 | AV16: =IF(E16="M3",L16,IF(E16="N2",L16,IF(E16="M9",L16,0))) -> 0 | AW16: =AR16 -> 3 | AX16: =IF(AW16="","",VLOOKUP(AW16,Nama_Buku,2)) -> BUKU PEMBANTU BANK | AY16: =AVERAGE(AU16+AV16) -> 0 | AZ16: 4 | BA16: =IF(AZ16="","",VLOOKUP(AZ16,Nama_Buku,2)) -> BUKU PEMBANTU BPP | BB16: =IF(E16="J1",L16,IF(E16="J2",L16,IF(E16="M4",L16,0))) -> 0 | BC16: =AZ16 -> 4 | BD16: =IF(BC16="","",VLOOKUP(BC16,Nama_Buku,2)) -> BUKU PEMBANTU BPP | BE16: =IF(E16="J3",L16,IF(E16="J4",L16,IF(E16="M5",L16,0))) -> 0 | BF16: 5 | BG16: =IF(BF16="","",VLOOKUP(BF16,Nama_Buku,2)) -> BUKU PEMBANTU UANG PERSEDIAAN | BH16: =IF(E16="B",L16,IF(E16="D1",L16,0)) -> 0 | BI16: =BF16 -> 5 | BJ16: =IF(BI16="","",VLOOKUP(BI16,Nama_Buku,2)) -> BUKU PEMBANTU UANG PERSEDIAAN | BK16: =IF(E16="D2",L16,IF(E16="H1",L16,IF(E16="H2",L16,IF(E16="J3",L16,IF(E16="K3",L16,IF(E16="N1",L16,IF(E16="N2",L16,0))))))) -> 0 | BL16: 6 | BM16: =IF(BL16="","",VLOOKUP(BL16,Nama_Buku,2)) -> BUKU PEMBANTU LS BENDAHARA | BN16: =IF(E16="C1",L16,IF(E16="C1",L16,IF(E16="R2",L16,IF(E16="L7",L16,0)))) -> 35520000 | BO16: =BL16 -> 6 | BP16: =IF(BO16="","",VLOOKUP(BO16,Nama_Buku,2)) -> BUKU PEMBANTU LS BENDAHARA | BQ16: =IF(E16="C2",L16,IF(E16="I1",L16,IF(E16="I2",L16,IF(E16="M9",L16,IF(E16="M3",L16,IF(E16="K3",L16,IF(E16="R1",L16,IF(E16="L6",L16,0)))))))) -> 0 | BR16: 7 | BS16: =IF(BR16="","",VLOOKUP(BR16,Nama_Buku,2)) -> BUKU PEMBANTU UANG MUKA PERJADIN | BT16: =IF(E16="K1",L16,IF(E16="K2",L16,0)) -> 0 | BU16: =BR16 -> 7 | BV16: =IF(BU16="","",VLOOKUP(BU16,Nama_Buku,2)) -> BUKU PEMBANTU UANG MUKA PERJADIN | BW16: =IF(E16="K3",L16,IF(E16="K4",L16,0)) -> 0 | BX16: 8 | BY16: =IF(BX16="","",VLOOKUP(BX16,Nama_Buku,2)) -> BUKU PEMBANTU PAJAK UP | BZ16: =IF(E16="M1",L16,IF(E16="M4",L16,IF(E16="M8",L16,0))) -> 0 | CA16: =BX16 -> 8 | CB16: =IF(CA16="","",VLOOKUP(CA16,Nama_Buku,2)) -> BUKU PEMBANTU PAJAK UP | CC16: =IF(E16="M2",L16,IF(E16="M3",L16,IF(E16="M5",L16,0))) -> 0 | CD16: 9 | CE16: =IF(CD16="","",VLOOKUP(CD16,Nama_Buku,2)) -> BUKU PEMBANTU BUNGA REKENING | CF16: =IF(E16="L1",L16,IF(E16="R1",L16,0)) -> 0 | CG16: =CD16 -> 9 | CH16: =IF(CG16="","",VLOOKUP(CG16,Nama_Buku,2)) -> BUKU PEMBANTU BUNGA REKENING | CI16: =IF(E16="L2",L16,IF(E16="L3",L16,0)) -> 0 | CJ16: 10 | CK16: =IF(CJ16="","",VLOOKUP(CJ16,Nama_Buku,2)) -> BUKU PEMBANTU PAJAK UP & LS | CL16: =IF(E16="M1",L16,IF(E16="M4",L16,IF(E16="M6",L16,IF(E16="M8",L16,0)))) -> 0 | CM16: =CJ16 -> 10 | CN16: =IF(CM16="","",VLOOKUP(CM16,Nama_Buku,2)) -> BUKU PEMBANTU PAJAK UP & LS | CO16: =IF(E16="M2",L16,IF(E16="M3",L16,IF(E16="M5",L16,IF(E16="M7",L16,IF(E16="M9",L16,0))))) -> 0 | CP16: =IF(E16="H1",L16,IF(E16="H2",L16,IF(E16="J3",L16,IF(E16="K3",L16,0)))) -> 0 | CQ16: =IF(E16="H1",M16,IF(E16="H2",M16,IF(E16="J3",M16,0))) -> 0 | CR16: =IF(E16="H1",N16,IF(E16="H2",N16,IF(E16="J3",N16,0))) -> 0 | CS16: 11 | CT16: =IF(CS16="","",VLOOKUP(CS16,Nama_Buku,2)) -> BUKU PENGESAHAN BELANJA | CU16: =IF(E16="C2",L16,IF(E16="I1",L16,IF(E16="I2",L16,IF(E16="K3",L16,IF(E16="M3",L16,IF(E16="M9",L16,0)))))) -> 0 | CV16: =CS16 -> 11 | CW16: =IF(CV16="","",VLOOKUP(CV16,Nama_Buku,2)) -> BUKU PENGESAHAN BELANJA | CX16: =IF(E16="C3",L16,0) -> 0 | CY16: 12 | CZ16: =IF(CY16="","",VLOOKUP(CY16,Nama_Buku,2)) -> BUKU PENGEMBALIAN BELANJA | DA16: =IF(E16="L4",L16,IF(E16="R2",L16,0)) -> 0 | DB16: =CY16 -> 12 | DC16: =IF(DB16="","",VLOOKUP(DB16,Nama_Buku,2)) -> BUKU PENGEMBALIAN BELANJA | DD16: =IF(E16="L5",L16,IF(E16="L5",L16,0)) -> 0
